<?xml version="1.0"?>
<robot xmlns:xacro="http://ros.org/wiki/xacro" name="hexapod">

	<!-- Properties -->
	<!-- <xacro:property name="base_width" value="0.31" />
	<xacro:property name="base_length" value="0.42" />
	<xacro:property name="base_height" value="0.18" /> -->

	<xacro:property name="norm" value="20" />

	<xacro:property name="base_width" value="${13/norm}" />
	<xacro:property name="base_length" value="${15.5/norm}" />
	<xacro:property name="base_height" value="${4.5/norm}" />

	<!-- Define macros for inertia  -->
	<xacro:macro name="box_inertia" params="m w h d">
		<inertial>
			<origin xyz="0 0 0" rpy="${pi/2} 0 ${pi/2}" />
			<mass value="${m}" />
			<inertia ixx="${(m/12) * (h*h + d*d)}" ixy="0.0" ixz="0.0" iyy="${(m/12) * (w*w + d*d)}"
				iyz="0.0" izz="${(m/12) * (w*w + h*h)}" />
		</inertial>
	</xacro:macro>

	<xacro:macro name="cylinder_inertia" params="m r h">
		<inertial>
			<origin xyz="0 0 0" rpy="${pi/2} 0 0" />
			<mass value="${m}" />
			<inertia ixx="${(m/12) * (3*r*r + h*h)}" ixy="0" ixz="0" iyy="${(m/12) * (3*r*r + h*h)}"
				iyz="0" izz="${(m/2) * (r*r)}" />
		</inertial>
	</xacro:macro>

	<xacro:macro name="sphere_inertia" params="m r">
		<inertial>
			<mass value="${m}" />
			<inertia ixx="${(2/5) * m * (r*r)}" ixy="0.0" ixz="0.0" iyy="${(2/5) * m * (r*r)}"
				iyz="0.0" izz="${(2/5) * m * (r*r)}" />
		</inertial>
	</xacro:macro>

	<!-- Build the body frame -->
	<link name="base_link">
		<collision>
			<geometry>
				<box size="${base_length} ${base_width} ${base_height}" />
			</geometry>
		</collision>

	</link>

	<!-- Robot Footprint -->
	<!-- <link name="base_footprint"> -->
		<!-- <xacro:box_inertia m="0" w="0" d="0" h="0" /> -->
	<!-- </link> -->

	<joint name="base_joint" type="fixed">
		<parent link="base_link" />
		<child link="thorax" />
		<origin xyz="0 0 0" rpy="0 0 0" />
	</joint>

	<link name="thorax">
		<visual>
			<origin xyz="0 0 0" rpy="0 0 0" />
			<geometry>
				<box size="${15.5/norm} ${13/norm} ${4.5/norm}" />
				<!-- <mesh filename="package://crab_description/meshes/thorax.STL" /> -->
			</geometry>
			<material name="grey">
				<color rgba="0.5 0.5 0.5 1" />
			</material>
		</visual>
		<collision>
			<origin xyz="0 0 0" rpy="0 0 0" />
			<geometry>
				<box size="${15.5/norm} ${13/norm} ${4.5/norm}" />
				<!-- <mesh filename="package://crab_description/meshes/thorax.STL" /> -->
			</geometry>
			<material name="grey">
				<color rgba="0.5 0.5 0.5 1" />
			</material>
		</collision>

		<!-- <collision>
			<geometry>
				<box size="${base_length} ${base_width} ${base_height}" />
			</geometry>
		</collision> -->
		<xacro:box_inertia m="0.03" w="${15.5/norm}" d="${13/norm}" h="${4.5/norm}" /> 
	</link>

	<!-- Pi parameter -->
	<xacro:property name="pi" value="3.1415926535897931" />

	<!-- Joint properties -->
	<xacro:property name="joint_lower_limit" value="-${1.5}" />
	<xacro:property name="joint_upper_limit" value="${1.5}" />
	<xacro:property name="joint_effort" value="10000" />
	<xacro:property name="joint_velocity" value="100" />

	<!-- Leg macros -->
	<xacro:macro name="leg" params="side num x y angle">

		<!-- Build leg -->
		<!-- joint to center of thorax -->
		<joint name="leg_center_joint_${side}${num}" type="fixed">
			<origin xyz="${x} ${y} 0" rpy="0 0 0" />
			<parent link="thorax" />
			<child link="leg_center_${side}${num}" />
		</joint>

		<link name="leg_center_${side}${num}" >
		<!-- THIS IS EXTRA -->
			<xacro:box_inertia m="0.001" w="${1/norm}" d="${1/norm}" h="${1/norm}" /> 
		</link>

		<joint name="coxa_joint_${side}${num}" type="revolute">
			<origin xyz="0 0 0" rpy="0 0 ${angle}" />
			<parent link="leg_center_${side}${num}" />
			<child link="coxa_${side}${num}" />
			<axis xyz="0 0 -1" />
			<limit lower="${joint_lower_limit}" upper="${joint_upper_limit}"
				effort="${joint_effort}" velocity="${joint_velocity}" />
		</joint>

		<transmission name="coxa_tran_${side}${num}">
			<type>transmission_interface/SimpleTransmission</type>
			<joint name="coxa_joint_${side}${num}">
				<hardwareInterface>hardware_interface/EffortJointInterface</hardwareInterface>
			</joint>
			<actuator name="coxa_motor_${side}${num}">
				<hardwareInterface>hardware_interface/EffortJointInterface</hardwareInterface>
				<mechanicalReduction>1</mechanicalReduction>
			</actuator>
    	</transmission>

		<link name="coxa_${side}${num}">
			<visual>
				<xacro:if value="${side == 'l'}">
				<origin xyz="${0.8/norm} ${0.5/norm} 0" rpy="0 0 0" />
			</xacro:if>
			<xacro:if value="${side == 'r'}">
				<origin xyz="${0.8/norm} -${0.5/norm} 0" rpy="0 0 0" />
			</xacro:if>
				<geometry>
					<box size="${3.3/norm} ${3.3/norm} ${3.3/norm}" />
				</geometry>
				<material name="">
					<color rgba="0.7 0.7 0 1" />
				</material>
			</visual>
			<collision>
				<xacro:if value="${side == 'l'}">
				<origin xyz="${0.8/norm} ${0.5/norm} 0" rpy="0 0 0" />
			</xacro:if>
			<xacro:if value="${side == 'r'}">
				<origin xyz="${0.8/norm} -${0.5/norm} 0" rpy="0 0 0" />
			</xacro:if>
				<geometry>
					<box size="${3.3/norm} ${3.3/norm} ${3.3/norm}" />
				</geometry>
				<material name="">
					<color rgba="0.7 0.7 0 1" />
				</material>
			</collision>
			<xacro:box_inertia m="0.01" w="${3.3/norm}" d="${3.3/norm}" h="${3.3/norm}" /> 
		</link>

		<joint name="femur_joint_${side}${num}" type="revolute">
			<origin xyz="${1/norm} 0 -${1/norm}" rpy="-${pi/2} 0 0" />
			<parent link="coxa_${side}${num}" />
			<child link="femur_${side}${num}" />
			<axis xyz="0 0 -1" />
			<limit lower="${joint_lower_limit}" upper="${joint_upper_limit}"
				effort="${joint_effort}" velocity="${joint_velocity}" />
		</joint>

		<transmission name="femur_tran_${side}${num}">
			<type>transmission_interface/SimpleTransmission</type>
			<joint name="femur_joint_${side}${num}">
				<hardwareInterface>hardware_interface/EffortJointInterface</hardwareInterface>
			</joint>
			<actuator name="femur_motor_${side}${num}">
				<hardwareInterface>hardware_interface/EffortJointInterface</hardwareInterface>
				<mechanicalReduction>1</mechanicalReduction>
			</actuator>
    	</transmission>

		<link name="femur_${side}${num}">
			<visual>
				<origin xyz="${(7/2)/norm} 0 0" rpy="0 0 0" />
				<geometry>
					<box size="${7/norm} ${1.5/norm} ${0.4/norm}" />
					<!-- <mesh filename="package://crab_description/meshes/femur_${side}.STL" /> -->
				</geometry>
				<material name="">
					<color rgba="0 0.7 0.7 1" />
				</material>
			</visual>
			<collision>
				<origin xyz="${(7/2)/norm} 0 0" rpy="0 0 0" />
				<geometry>
					<box size="${7/norm} ${1.5/norm} ${0.4/norm}" />
					<!-- <mesh filename="package://crab_description/meshes/femur_${side}.STL" /> -->
				</geometry>
				<material name="">
					<color rgba="0 0.7 0.7 1" />
				</material>
			</collision>
			<xacro:box_inertia m="0.01" w="${7/norm}" d="${1.5/norm}" h="${0.4/norm}" /> 
		</link>

		<joint name="tibia_joint_${side}${num}" type="revolute">
			<origin xyz="${((7-0.4)/norm)} 0 0" rpy="${pi} 0 ${pi/2}" />
			<parent link="femur_${side}${num}" />
			<child link="tibia_${side}${num}" />
			<axis xyz="0 0 1" />
			<limit lower="${joint_lower_limit}" upper="${joint_upper_limit}"
				effort="${joint_effort}" velocity="${joint_velocity}" />
		</joint>

		<transmission name="tibia_tran_${side}${num}">
			<type>transmission_interface/SimpleTransmission</type>
			<joint name="tibia_joint_${side}${num}">
				<hardwareInterface>hardware_interface/EffortJointInterface</hardwareInterface>
			</joint>
			<actuator name="tibia_motor_${side}${num}">
				<hardwareInterface>hardware_interface/EffortJointInterface</hardwareInterface>
				<mechanicalReduction>1</mechanicalReduction>
			</actuator>
    	</transmission>

		<link name="tibia_${side}${num}">
			<visual>
				<origin xyz="${((9-1.4)/2)/norm} 0 ${2/norm}" rpy="0 0 0.06" />
				<geometry>
					<box size="${9/norm} ${2/norm} ${0.5/norm}" />
					<!-- <mesh filename="package://crab_description/meshes/tibia_${side}.STL" /> -->
				</geometry>
				<material name="">
					<color rgba="0.7 0 0.7 1" />
				</material>
			</visual>
			<collision>
				<origin xyz="${((9-1.4)/2)/norm} 0 ${2/norm}" rpy="0 0 0.06" />
				<geometry>
					<box size="${9/norm} ${2/norm} ${0.5/norm}" />
					<!-- <mesh filename="package://crab_description/meshes/tibia_${side}.STL" /> -->
				</geometry>
				<surface>
					<friction>
					<ode>
						<mu>10000.01</mu>
						<mu2>10000.01</mu2>
					</ode>
					</friction>
				</surface>
				<material name="">
					<color rgba="0.7 0 0.7 1" />
				</material>
			</collision>
			<!-- TODO CHECK INERTIA ORDER!!!! -->
			<xacro:box_inertia m="0.01" w="${9/norm}" d="${2/norm}" h="${0.5/norm}" /> 
		</link>

		<joint name="tibia_foot_joint_${side}${num}" type="fixed">
			<origin xyz="0.117 0 0" rpy="0 0 0" />
			<parent link="tibia_${side}${num}" />
			<child link="tibia_foot_${side}${num}" />
		</joint>

		<link name="tibia_foot_${side}${num}" />
	</xacro:macro>

	<xacro:property name="x_far_offset" value="${(15.5/2)/norm}" />
	<xacro:property name="y_far_offset" value="${(13/2)/norm}" />

	<!-- Build robot model -->
	<xacro:leg side="r" num="1" x="${x_far_offset}" y="-${y_far_offset}" angle="-${pi/3}" />
	<xacro:leg side="r" num="2" x="0" y="-${y_far_offset}" angle="-${pi/2}" />
	<xacro:leg side="r" num="3" x="-${x_far_offset}" y="-${y_far_offset}" angle="-${pi*2/3}" />
	<xacro:leg side="l" num="1" x="${x_far_offset}" y="${y_far_offset}" angle="${pi/3}" />
	<xacro:leg side="l" num="2" x="0" y="${y_far_offset}" angle="${pi/2}" />
	<xacro:leg side="l" num="3" x="-${x_far_offset}" y="${y_far_offset}" angle="${pi*2/3}" />


	<gazebo>
        <plugin name="gazebo_ros_control" filename="libgazebo_ros_control.so">
            <robotNamespace>/hexapod</robotNamespace>
        </plugin>
		<self_collide>1</self_collide>
    </gazebo>

	  <!-- Contact Sensor -->
    <gazebo reference="base_link">
        <material>Gazebo/Blue</material>
        <kp>1000.0</kp>
        <kd>1000.0</kd>
        <mu1>1000000.0</mu1>
        <mu2>1000000.0</mu2>


        <sensor name="contactsensor_sensor" type="contact">
          <always_on>true</always_on>
          <contact>
            <collision>base_link_fixed_joint_lump__thorax_collision_1</collision>
          </contact>
          <plugin name="bumper0_plugin" filename="libgazebo_ros_bumper.so">
            <bumperTopicName>contactsensor_state</bumperTopicName>
            <frameName>contactsensor_link</frameName>
          </plugin>
        </sensor>

    </gazebo>

<!-- ODOM sensor -->
	 <gazebo>
        <plugin name="p3d_base_controller" filename="libgazebo_ros_p3d.so">
            <alwaysOn>true</alwaysOn>
            <!--<updateRate>50.0</updateRate>-->
            <bodyName>base_link</bodyName>
            <topicName>odom</topicName>
            <gaussianNoise>0.01</gaussianNoise>
            <frameName>world</frameName>
            <xyzOffsets>0 0 0</xyzOffsets>
            <rpyOffsets>0 0 0</rpyOffsets>
        </plugin>
    </gazebo>

	<!-- IMU sensor -->
	 <gazebo>
        <plugin name="gazebo_ros_imu_controller" filename="libgazebo_ros_imu.so">
          <robotNamespace>/hexapod</robotNamespace>
          <topicName>imu/data</topicName>
          <serviceName>imu/service</serviceName>
          <bodyName>base_link</bodyName>
          <gaussianNoise>0</gaussianNoise>
          <rpyOffsets>0 0 0</rpyOffsets>
          <!--<updateRate>50.0</updateRate>-->
          <alwaysOn>true</alwaysOn>
          <gaussianNoise>0</gaussianNoise>
        </plugin>
    </gazebo>

	<xacro:macro name="friction_set" params="side num">
		<gazebo reference="femur_${side}${num}">
			<mu1>10000.9</mu1>
			<mu2>10000.9</mu2>
			<minDepth>0.001</minDepth>
			<kp>100000000</kp>
			<kd>1</kd>
		</gazebo>
	</xacro:macro>

<xacro:friction_set side="l" num="1"/>
<xacro:friction_set side="l" num="2" />
<xacro:friction_set side="l" num="3" />
<xacro:friction_set side="r" num="1" />
<xacro:friction_set side="r" num="2" />
<xacro:friction_set side="r" num="3" />

</robot>