<?xml version="1.0" ?>
<!-- =================================================================================== -->
<!-- |    This document was autogenerated by xacro from crab_model.xacro               | -->
<!-- |    EDITING THIS FILE BY HAND IS NOT RECOMMENDED                                 | -->
<!-- =================================================================================== -->
<robot name="hexapod">
  <!-- Properties -->
  <!-- <xacro:property name="base_width" value="0.31" />
	<xacro:property name="base_length" value="0.42" />
	<xacro:property name="base_height" value="0.18" /> -->
  <!-- Build the body frame -->
  <link name="base_link">
    <collision>
      <geometry>
        <box size="0.775 0.65 0.225"/>
      </geometry>
    </collision>
  </link>
  <!-- Robot Footprint -->
  <!-- <link name="base_footprint"> -->
  <!-- <xacro:box_inertia m="0" w="0" d="0" h="0" /> -->
  <!-- </link> -->
  <joint name="base_joint" type="fixed">
    <parent link="base_link"/>
    <child link="thorax"/>
    <origin rpy="0 0 0" xyz="0 0 0"/>
  </joint>
  <link name="thorax">
    <visual>
      <origin rpy="0 0 0" xyz="0 0 0"/>
      <geometry>
        <box size="0.775 0.65 0.225"/>
        <!-- <mesh filename="package://crab_description/meshes/thorax.STL" /> -->
      </geometry>
      <material name="grey">
        <color rgba="0.5 0.5 0.5 1"/>
      </material>
    </visual>
    <collision>
      <origin rpy="0 0 0" xyz="0 0 0"/>
      <geometry>
        <box size="0.775 0.65 0.225"/>
        <!-- <mesh filename="package://crab_description/meshes/thorax.STL" /> -->
      </geometry>
      <material name="grey">
        <color rgba="0.5 0.5 0.5 1"/>
      </material>
    </collision>
    <inertial>
      <origin rpy="1.5707963267948966 0 1.5707963267948966" xyz="0 0 0"/>
      <mass value="0.03"/>
      <inertia ixx="0.0011828125" ixy="0.0" ixz="0.0" iyy="0.0025578125" iyz="0.0" izz="0.0016281250000000002"/>
    </inertial>
  </link>
  <!-- Build leg -->
  <!-- joint to center of thorax -->
  <joint name="leg_center_joint_r1" type="fixed">
    <origin rpy="0 0 0" xyz="0.3875 -0.325 0"/>
    <parent link="thorax"/>
    <child link="leg_center_r1"/>
  </joint>
  <link name="leg_center_r1">
    <inertial>
      <origin rpy="1.5707963267948966 0 1.5707963267948966" xyz="0 0 0"/>
      <mass value="0.001"/>
      <inertia ixx="4.166666666666667e-07" ixy="0.0" ixz="0.0" iyy="4.166666666666667e-07" iyz="0.0" izz="4.166666666666667e-07"/>
    </inertial>
  </link>
  <joint name="coxa_joint_r1" type="revolute">
    <origin rpy="0 0 -1.0471975511965976" xyz="0 0 0"/>
    <parent link="leg_center_r1"/>
    <child link="coxa_r1"/>
    <axis xyz="0 0 -1"/>
    <limit effort="10000" lower="-1.5" upper="1.5" velocity="100"/>
  </joint>
  <transmission name="coxa_tran_r1">
    <type>transmission_interface/SimpleTransmission</type>
    <joint name="coxa_joint_r1">
      <hardwareInterface>hardware_interface/EffortJointInterface</hardwareInterface>
    </joint>
    <actuator name="coxa_motor_r1">
      <hardwareInterface>hardware_interface/EffortJointInterface</hardwareInterface>
      <mechanicalReduction>1</mechanicalReduction>
    </actuator>
  </transmission>
  <link name="coxa_r1">
    <visual>
      <origin rpy="0 0 0" xyz="0.04 -0.025 0"/>
      <geometry>
        <box size="0.16499999999999998 0.16499999999999998 0.16499999999999998"/>
      </geometry>
      <material name="">
        <color rgba="0.7 0.7 0 1"/>
      </material>
    </visual>
    <collision>
      <origin rpy="0 0 0" xyz="0.04 -0.025 0"/>
      <geometry>
        <box size="0.16499999999999998 0.16499999999999998 0.16499999999999998"/>
      </geometry>
      <material name="">
        <color rgba="0.7 0.7 0 1"/>
      </material>
    </collision>
    <inertial>
      <origin rpy="1.5707963267948966 0 1.5707963267948966" xyz="0 0 0"/>
      <mass value="0.01"/>
      <inertia ixx="4.537499999999999e-05" ixy="0.0" ixz="0.0" iyy="4.537499999999999e-05" iyz="0.0" izz="4.537499999999999e-05"/>
    </inertial>
  </link>
  <joint name="femur_joint_r1" type="revolute">
    <origin rpy="-1.5707963267948966 0 0" xyz="0.05 0 -0.05"/>
    <parent link="coxa_r1"/>
    <child link="femur_r1"/>
    <axis xyz="0 0 -1"/>
    <limit effort="10000" lower="-1.5" upper="1.5" velocity="100"/>
  </joint>
  <transmission name="femur_tran_r1">
    <type>transmission_interface/SimpleTransmission</type>
    <joint name="femur_joint_r1">
      <hardwareInterface>hardware_interface/EffortJointInterface</hardwareInterface>
    </joint>
    <actuator name="femur_motor_r1">
      <hardwareInterface>hardware_interface/EffortJointInterface</hardwareInterface>
      <mechanicalReduction>1</mechanicalReduction>
    </actuator>
  </transmission>
  <link name="femur_r1">
    <visual>
      <origin rpy="0 0 0" xyz="0.175 0 0"/>
      <geometry>
        <box size="0.35 0.075 0.02"/>
        <!-- <mesh filename="package://crab_description/meshes/femur_${side}.STL" /> -->
      </geometry>
      <material name="">
        <color rgba="0 0.7 0.7 1"/>
      </material>
    </visual>
    <collision>
      <origin rpy="0 0 0" xyz="0.175 0 0"/>
      <geometry>
        <box size="0.35 0.075 0.02"/>
        <!-- <mesh filename="package://crab_description/meshes/femur_${side}.STL" /> -->
      </geometry>
      <material name="">
        <color rgba="0 0.7 0.7 1"/>
      </material>
    </collision>
    <inertial>
      <origin rpy="1.5707963267948966 0 1.5707963267948966" xyz="0 0 0"/>
      <mass value="0.01"/>
      <inertia ixx="5.020833333333334e-06" ixy="0.0" ixz="0.0" iyy="0.00010677083333333332" iyz="0.0" izz="0.00010241666666666666"/>
    </inertial>
  </link>
  <joint name="tibia_joint_r1" type="revolute">
    <origin rpy="3.141592653589793 0 1.5707963267948966" xyz="0.32999999999999996 0 0"/>
    <parent link="femur_r1"/>
    <child link="tibia_r1"/>
    <axis xyz="0 0 1"/>
    <limit effort="10000" lower="-1.5" upper="1.5" velocity="100"/>
  </joint>
  <transmission name="tibia_tran_r1">
    <type>transmission_interface/SimpleTransmission</type>
    <joint name="tibia_joint_r1">
      <hardwareInterface>hardware_interface/EffortJointInterface</hardwareInterface>
    </joint>
    <actuator name="tibia_motor_r1">
      <hardwareInterface>hardware_interface/EffortJointInterface</hardwareInterface>
      <mechanicalReduction>1</mechanicalReduction>
    </actuator>
  </transmission>
  <link name="tibia_r1">
    <visual>
      <origin rpy="0 0 0.06" xyz="0.19 0 0.1"/>
      <geometry>
        <box size="0.45 0.1 0.025"/>
        <!-- <mesh filename="package://crab_description/meshes/tibia_${side}.STL" /> -->
      </geometry>
      <material name="">
        <color rgba="0.7 0 0.7 1"/>
      </material>
    </visual>
    <collision>
      <origin rpy="0 0 0.06" xyz="0.19 0 0.1"/>
      <geometry>
        <box size="0.45 0.1 0.025"/>
        <!-- <mesh filename="package://crab_description/meshes/tibia_${side}.STL" /> -->
      </geometry>
      <surface>
        <friction>
          <ode>
            <mu>10000.01</mu>
            <mu2>10000.01</mu2>
          </ode>
        </friction>
      </surface>
      <material name="">
        <color rgba="0.7 0 0.7 1"/>
      </material>
    </collision>
    <inertial>
      <origin rpy="1.5707963267948966 0 1.5707963267948966" xyz="0 0 0"/>
      <mass value="0.01"/>
      <inertia ixx="8.854166666666669e-06" ixy="0.0" ixz="0.0" iyy="0.00017708333333333337" iyz="0.0" izz="0.00016927083333333334"/>
    </inertial>
  </link>
  <joint name="tibia_foot_joint_r1" type="fixed">
    <origin rpy="0 0 0" xyz="0.117 0 0"/>
    <parent link="tibia_r1"/>
    <child link="tibia_foot_r1"/>
  </joint>
  <link name="tibia_foot_r1"/>
  <!-- Build leg -->
  <!-- joint to center of thorax -->
  <joint name="leg_center_joint_r2" type="fixed">
    <origin rpy="0 0 0" xyz="0 -0.325 0"/>
    <parent link="thorax"/>
    <child link="leg_center_r2"/>
  </joint>
  <link name="leg_center_r2">
    <inertial>
      <origin rpy="1.5707963267948966 0 1.5707963267948966" xyz="0 0 0"/>
      <mass value="0.001"/>
      <inertia ixx="4.166666666666667e-07" ixy="0.0" ixz="0.0" iyy="4.166666666666667e-07" iyz="0.0" izz="4.166666666666667e-07"/>
    </inertial>
  </link>
  <joint name="coxa_joint_r2" type="revolute">
    <origin rpy="0 0 -1.5707963267948966" xyz="0 0 0"/>
    <parent link="leg_center_r2"/>
    <child link="coxa_r2"/>
    <axis xyz="0 0 -1"/>
    <limit effort="10000" lower="-1.5" upper="1.5" velocity="100"/>
  </joint>
  <transmission name="coxa_tran_r2">
    <type>transmission_interface/SimpleTransmission</type>
    <joint name="coxa_joint_r2">
      <hardwareInterface>hardware_interface/EffortJointInterface</hardwareInterface>
    </joint>
    <actuator name="coxa_motor_r2">
      <hardwareInterface>hardware_interface/EffortJointInterface</hardwareInterface>
      <mechanicalReduction>1</mechanicalReduction>
    </actuator>
  </transmission>
  <link name="coxa_r2">
    <visual>
      <origin rpy="0 0 0" xyz="0.04 -0.025 0"/>
      <geometry>
        <box size="0.16499999999999998 0.16499999999999998 0.16499999999999998"/>
      </geometry>
      <material name="">
        <color rgba="0.7 0.7 0 1"/>
      </material>
    </visual>
    <collision>
      <origin rpy="0 0 0" xyz="0.04 -0.025 0"/>
      <geometry>
        <box size="0.16499999999999998 0.16499999999999998 0.16499999999999998"/>
      </geometry>
      <material name="">
        <color rgba="0.7 0.7 0 1"/>
      </material>
    </collision>
    <inertial>
      <origin rpy="1.5707963267948966 0 1.5707963267948966" xyz="0 0 0"/>
      <mass value="0.01"/>
      <inertia ixx="4.537499999999999e-05" ixy="0.0" ixz="0.0" iyy="4.537499999999999e-05" iyz="0.0" izz="4.537499999999999e-05"/>
    </inertial>
  </link>
  <joint name="femur_joint_r2" type="revolute">
    <origin rpy="-1.5707963267948966 0 0" xyz="0.05 0 -0.05"/>
    <parent link="coxa_r2"/>
    <child link="femur_r2"/>
    <axis xyz="0 0 -1"/>
    <limit effort="10000" lower="-1.5" upper="1.5" velocity="100"/>
  </joint>
  <transmission name="femur_tran_r2">
    <type>transmission_interface/SimpleTransmission</type>
    <joint name="femur_joint_r2">
      <hardwareInterface>hardware_interface/EffortJointInterface</hardwareInterface>
    </joint>
    <actuator name="femur_motor_r2">
      <hardwareInterface>hardware_interface/EffortJointInterface</hardwareInterface>
      <mechanicalReduction>1</mechanicalReduction>
    </actuator>
  </transmission>
  <link name="femur_r2">
    <visual>
      <origin rpy="0 0 0" xyz="0.175 0 0"/>
      <geometry>
        <box size="0.35 0.075 0.02"/>
        <!-- <mesh filename="package://crab_description/meshes/femur_${side}.STL" /> -->
      </geometry>
      <material name="">
        <color rgba="0 0.7 0.7 1"/>
      </material>
    </visual>
    <collision>
      <origin rpy="0 0 0" xyz="0.175 0 0"/>
      <geometry>
        <box size="0.35 0.075 0.02"/>
        <!-- <mesh filename="package://crab_description/meshes/femur_${side}.STL" /> -->
      </geometry>
      <material name="">
        <color rgba="0 0.7 0.7 1"/>
      </material>
    </collision>
    <inertial>
      <origin rpy="1.5707963267948966 0 1.5707963267948966" xyz="0 0 0"/>
      <mass value="0.01"/>
      <inertia ixx="5.020833333333334e-06" ixy="0.0" ixz="0.0" iyy="0.00010677083333333332" iyz="0.0" izz="0.00010241666666666666"/>
    </inertial>
  </link>
  <joint name="tibia_joint_r2" type="revolute">
    <origin rpy="3.141592653589793 0 1.5707963267948966" xyz="0.32999999999999996 0 0"/>
    <parent link="femur_r2"/>
    <child link="tibia_r2"/>
    <axis xyz="0 0 1"/>
    <limit effort="10000" lower="-1.5" upper="1.5" velocity="100"/>
  </joint>
  <transmission name="tibia_tran_r2">
    <type>transmission_interface/SimpleTransmission</type>
    <joint name="tibia_joint_r2">
      <hardwareInterface>hardware_interface/EffortJointInterface</hardwareInterface>
    </joint>
    <actuator name="tibia_motor_r2">
      <hardwareInterface>hardware_interface/EffortJointInterface</hardwareInterface>
      <mechanicalReduction>1</mechanicalReduction>
    </actuator>
  </transmission>
  <link name="tibia_r2">
    <visual>
      <origin rpy="0 0 0.06" xyz="0.19 0 0.1"/>
      <geometry>
        <box size="0.45 0.1 0.025"/>
        <!-- <mesh filename="package://crab_description/meshes/tibia_${side}.STL" /> -->
      </geometry>
      <material name="">
        <color rgba="0.7 0 0.7 1"/>
      </material>
    </visual>
    <collision>
      <origin rpy="0 0 0.06" xyz="0.19 0 0.1"/>
      <geometry>
        <box size="0.45 0.1 0.025"/>
        <!-- <mesh filename="package://crab_description/meshes/tibia_${side}.STL" /> -->
      </geometry>
      <surface>
        <friction>
          <ode>
            <mu>10000.01</mu>
            <mu2>10000.01</mu2>
          </ode>
        </friction>
      </surface>
      <material name="">
        <color rgba="0.7 0 0.7 1"/>
      </material>
    </collision>
    <inertial>
      <origin rpy="1.5707963267948966 0 1.5707963267948966" xyz="0 0 0"/>
      <mass value="0.01"/>
      <inertia ixx="8.854166666666669e-06" ixy="0.0" ixz="0.0" iyy="0.00017708333333333337" iyz="0.0" izz="0.00016927083333333334"/>
    </inertial>
  </link>
  <joint name="tibia_foot_joint_r2" type="fixed">
    <origin rpy="0 0 0" xyz="0.117 0 0"/>
    <parent link="tibia_r2"/>
    <child link="tibia_foot_r2"/>
  </joint>
  <link name="tibia_foot_r2"/>
  <!-- Build leg -->
  <!-- joint to center of thorax -->
  <joint name="leg_center_joint_r3" type="fixed">
    <origin rpy="0 0 0" xyz="-0.3875 -0.325 0"/>
    <parent link="thorax"/>
    <child link="leg_center_r3"/>
  </joint>
  <link name="leg_center_r3">
    <inertial>
      <origin rpy="1.5707963267948966 0 1.5707963267948966" xyz="0 0 0"/>
      <mass value="0.001"/>
      <inertia ixx="4.166666666666667e-07" ixy="0.0" ixz="0.0" iyy="4.166666666666667e-07" iyz="0.0" izz="4.166666666666667e-07"/>
    </inertial>
  </link>
  <joint name="coxa_joint_r3" type="revolute">
    <origin rpy="0 0 -2.0943951023931953" xyz="0 0 0"/>
    <parent link="leg_center_r3"/>
    <child link="coxa_r3"/>
    <axis xyz="0 0 -1"/>
    <limit effort="10000" lower="-1.5" upper="1.5" velocity="100"/>
  </joint>
  <transmission name="coxa_tran_r3">
    <type>transmission_interface/SimpleTransmission</type>
    <joint name="coxa_joint_r3">
      <hardwareInterface>hardware_interface/EffortJointInterface</hardwareInterface>
    </joint>
    <actuator name="coxa_motor_r3">
      <hardwareInterface>hardware_interface/EffortJointInterface</hardwareInterface>
      <mechanicalReduction>1</mechanicalReduction>
    </actuator>
  </transmission>
  <link name="coxa_r3">
    <visual>
      <origin rpy="0 0 0" xyz="0.04 -0.025 0"/>
      <geometry>
        <box size="0.16499999999999998 0.16499999999999998 0.16499999999999998"/>
      </geometry>
      <material name="">
        <color rgba="0.7 0.7 0 1"/>
      </material>
    </visual>
    <collision>
      <origin rpy="0 0 0" xyz="0.04 -0.025 0"/>
      <geometry>
        <box size="0.16499999999999998 0.16499999999999998 0.16499999999999998"/>
      </geometry>
      <material name="">
        <color rgba="0.7 0.7 0 1"/>
      </material>
    </collision>
    <inertial>
      <origin rpy="1.5707963267948966 0 1.5707963267948966" xyz="0 0 0"/>
      <mass value="0.01"/>
      <inertia ixx="4.537499999999999e-05" ixy="0.0" ixz="0.0" iyy="4.537499999999999e-05" iyz="0.0" izz="4.537499999999999e-05"/>
    </inertial>
  </link>
  <joint name="femur_joint_r3" type="revolute">
    <origin rpy="-1.5707963267948966 0 0" xyz="0.05 0 -0.05"/>
    <parent link="coxa_r3"/>
    <child link="femur_r3"/>
    <axis xyz="0 0 -1"/>
    <limit effort="10000" lower="-1.5" upper="1.5" velocity="100"/>
  </joint>
  <transmission name="femur_tran_r3">
    <type>transmission_interface/SimpleTransmission</type>
    <joint name="femur_joint_r3">
      <hardwareInterface>hardware_interface/EffortJointInterface</hardwareInterface>
    </joint>
    <actuator name="femur_motor_r3">
      <hardwareInterface>hardware_interface/EffortJointInterface</hardwareInterface>
      <mechanicalReduction>1</mechanicalReduction>
    </actuator>
  </transmission>
  <link name="femur_r3">
    <visual>
      <origin rpy="0 0 0" xyz="0.175 0 0"/>
      <geometry>
        <box size="0.35 0.075 0.02"/>
        <!-- <mesh filename="package://crab_description/meshes/femur_${side}.STL" /> -->
      </geometry>
      <material name="">
        <color rgba="0 0.7 0.7 1"/>
      </material>
    </visual>
    <collision>
      <origin rpy="0 0 0" xyz="0.175 0 0"/>
      <geometry>
        <box size="0.35 0.075 0.02"/>
        <!-- <mesh filename="package://crab_description/meshes/femur_${side}.STL" /> -->
      </geometry>
      <material name="">
        <color rgba="0 0.7 0.7 1"/>
      </material>
    </collision>
    <inertial>
      <origin rpy="1.5707963267948966 0 1.5707963267948966" xyz="0 0 0"/>
      <mass value="0.01"/>
      <inertia ixx="5.020833333333334e-06" ixy="0.0" ixz="0.0" iyy="0.00010677083333333332" iyz="0.0" izz="0.00010241666666666666"/>
    </inertial>
  </link>
  <joint name="tibia_joint_r3" type="revolute">
    <origin rpy="3.141592653589793 0 1.5707963267948966" xyz="0.32999999999999996 0 0"/>
    <parent link="femur_r3"/>
    <child link="tibia_r3"/>
    <axis xyz="0 0 1"/>
    <limit effort="10000" lower="-1.5" upper="1.5" velocity="100"/>
  </joint>
  <transmission name="tibia_tran_r3">
    <type>transmission_interface/SimpleTransmission</type>
    <joint name="tibia_joint_r3">
      <hardwareInterface>hardware_interface/EffortJointInterface</hardwareInterface>
    </joint>
    <actuator name="tibia_motor_r3">
      <hardwareInterface>hardware_interface/EffortJointInterface</hardwareInterface>
      <mechanicalReduction>1</mechanicalReduction>
    </actuator>
  </transmission>
  <link name="tibia_r3">
    <visual>
      <origin rpy="0 0 0.06" xyz="0.19 0 0.1"/>
      <geometry>
        <box size="0.45 0.1 0.025"/>
        <!-- <mesh filename="package://crab_description/meshes/tibia_${side}.STL" /> -->
      </geometry>
      <material name="">
        <color rgba="0.7 0 0.7 1"/>
      </material>
    </visual>
    <collision>
      <origin rpy="0 0 0.06" xyz="0.19 0 0.1"/>
      <geometry>
        <box size="0.45 0.1 0.025"/>
        <!-- <mesh filename="package://crab_description/meshes/tibia_${side}.STL" /> -->
      </geometry>
      <surface>
        <friction>
          <ode>
            <mu>10000.01</mu>
            <mu2>10000.01</mu2>
          </ode>
        </friction>
      </surface>
      <material name="">
        <color rgba="0.7 0 0.7 1"/>
      </material>
    </collision>
    <inertial>
      <origin rpy="1.5707963267948966 0 1.5707963267948966" xyz="0 0 0"/>
      <mass value="0.01"/>
      <inertia ixx="8.854166666666669e-06" ixy="0.0" ixz="0.0" iyy="0.00017708333333333337" iyz="0.0" izz="0.00016927083333333334"/>
    </inertial>
  </link>
  <joint name="tibia_foot_joint_r3" type="fixed">
    <origin rpy="0 0 0" xyz="0.117 0 0"/>
    <parent link="tibia_r3"/>
    <child link="tibia_foot_r3"/>
  </joint>
  <link name="tibia_foot_r3"/>
  <!-- Build leg -->
  <!-- joint to center of thorax -->
  <joint name="leg_center_joint_l1" type="fixed">
    <origin rpy="0 0 0" xyz="0.3875 0.325 0"/>
    <parent link="thorax"/>
    <child link="leg_center_l1"/>
  </joint>
  <link name="leg_center_l1">
    <inertial>
      <origin rpy="1.5707963267948966 0 1.5707963267948966" xyz="0 0 0"/>
      <mass value="0.001"/>
      <inertia ixx="4.166666666666667e-07" ixy="0.0" ixz="0.0" iyy="4.166666666666667e-07" iyz="0.0" izz="4.166666666666667e-07"/>
    </inertial>
  </link>
  <joint name="coxa_joint_l1" type="revolute">
    <origin rpy="0 0 1.0471975511965976" xyz="0 0 0"/>
    <parent link="leg_center_l1"/>
    <child link="coxa_l1"/>
    <axis xyz="0 0 -1"/>
    <limit effort="10000" lower="-1.5" upper="1.5" velocity="100"/>
  </joint>
  <transmission name="coxa_tran_l1">
    <type>transmission_interface/SimpleTransmission</type>
    <joint name="coxa_joint_l1">
      <hardwareInterface>hardware_interface/EffortJointInterface</hardwareInterface>
    </joint>
    <actuator name="coxa_motor_l1">
      <hardwareInterface>hardware_interface/EffortJointInterface</hardwareInterface>
      <mechanicalReduction>1</mechanicalReduction>
    </actuator>
  </transmission>
  <link name="coxa_l1">
    <visual>
      <origin rpy="0 0 0" xyz="0.04 0.025 0"/>
      <geometry>
        <box size="0.16499999999999998 0.16499999999999998 0.16499999999999998"/>
      </geometry>
      <material name="">
        <color rgba="0.7 0.7 0 1"/>
      </material>
    </visual>
    <collision>
      <origin rpy="0 0 0" xyz="0.04 0.025 0"/>
      <geometry>
        <box size="0.16499999999999998 0.16499999999999998 0.16499999999999998"/>
      </geometry>
      <material name="">
        <color rgba="0.7 0.7 0 1"/>
      </material>
    </collision>
    <inertial>
      <origin rpy="1.5707963267948966 0 1.5707963267948966" xyz="0 0 0"/>
      <mass value="0.01"/>
      <inertia ixx="4.537499999999999e-05" ixy="0.0" ixz="0.0" iyy="4.537499999999999e-05" iyz="0.0" izz="4.537499999999999e-05"/>
    </inertial>
  </link>
  <joint name="femur_joint_l1" type="revolute">
    <origin rpy="-1.5707963267948966 0 0" xyz="0.05 0 -0.05"/>
    <parent link="coxa_l1"/>
    <child link="femur_l1"/>
    <axis xyz="0 0 -1"/>
    <limit effort="10000" lower="-1.5" upper="1.5" velocity="100"/>
  </joint>
  <transmission name="femur_tran_l1">
    <type>transmission_interface/SimpleTransmission</type>
    <joint name="femur_joint_l1">
      <hardwareInterface>hardware_interface/EffortJointInterface</hardwareInterface>
    </joint>
    <actuator name="femur_motor_l1">
      <hardwareInterface>hardware_interface/EffortJointInterface</hardwareInterface>
      <mechanicalReduction>1</mechanicalReduction>
    </actuator>
  </transmission>
  <link name="femur_l1">
    <visual>
      <origin rpy="0 0 0" xyz="0.175 0 0"/>
      <geometry>
        <box size="0.35 0.075 0.02"/>
        <!-- <mesh filename="package://crab_description/meshes/femur_${side}.STL" /> -->
      </geometry>
      <material name="">
        <color rgba="0 0.7 0.7 1"/>
      </material>
    </visual>
    <collision>
      <origin rpy="0 0 0" xyz="0.175 0 0"/>
      <geometry>
        <box size="0.35 0.075 0.02"/>
        <!-- <mesh filename="package://crab_description/meshes/femur_${side}.STL" /> -->
      </geometry>
      <material name="">
        <color rgba="0 0.7 0.7 1"/>
      </material>
    </collision>
    <inertial>
      <origin rpy="1.5707963267948966 0 1.5707963267948966" xyz="0 0 0"/>
      <mass value="0.01"/>
      <inertia ixx="5.020833333333334e-06" ixy="0.0" ixz="0.0" iyy="0.00010677083333333332" iyz="0.0" izz="0.00010241666666666666"/>
    </inertial>
  </link>
  <joint name="tibia_joint_l1" type="revolute">
    <origin rpy="3.141592653589793 0 1.5707963267948966" xyz="0.32999999999999996 0 0"/>
    <parent link="femur_l1"/>
    <child link="tibia_l1"/>
    <axis xyz="0 0 1"/>
    <limit effort="10000" lower="-1.5" upper="1.5" velocity="100"/>
  </joint>
  <transmission name="tibia_tran_l1">
    <type>transmission_interface/SimpleTransmission</type>
    <joint name="tibia_joint_l1">
      <hardwareInterface>hardware_interface/EffortJointInterface</hardwareInterface>
    </joint>
    <actuator name="tibia_motor_l1">
      <hardwareInterface>hardware_interface/EffortJointInterface</hardwareInterface>
      <mechanicalReduction>1</mechanicalReduction>
    </actuator>
  </transmission>
  <link name="tibia_l1">
    <visual>
      <origin rpy="0 0 0.06" xyz="0.19 0 0.1"/>
      <geometry>
        <box size="0.45 0.1 0.025"/>
        <!-- <mesh filename="package://crab_description/meshes/tibia_${side}.STL" /> -->
      </geometry>
      <material name="">
        <color rgba="0.7 0 0.7 1"/>
      </material>
    </visual>
    <collision>
      <origin rpy="0 0 0.06" xyz="0.19 0 0.1"/>
      <geometry>
        <box size="0.45 0.1 0.025"/>
        <!-- <mesh filename="package://crab_description/meshes/tibia_${side}.STL" /> -->
      </geometry>
      <surface>
        <friction>
          <ode>
            <mu>10000.01</mu>
            <mu2>10000.01</mu2>
          </ode>
        </friction>
      </surface>
      <material name="">
        <color rgba="0.7 0 0.7 1"/>
      </material>
    </collision>
    <inertial>
      <origin rpy="1.5707963267948966 0 1.5707963267948966" xyz="0 0 0"/>
      <mass value="0.01"/>
      <inertia ixx="8.854166666666669e-06" ixy="0.0" ixz="0.0" iyy="0.00017708333333333337" iyz="0.0" izz="0.00016927083333333334"/>
    </inertial>
  </link>
  <joint name="tibia_foot_joint_l1" type="fixed">
    <origin rpy="0 0 0" xyz="0.117 0 0"/>
    <parent link="tibia_l1"/>
    <child link="tibia_foot_l1"/>
  </joint>
  <link name="tibia_foot_l1"/>
  <!-- Build leg -->
  <!-- joint to center of thorax -->
  <joint name="leg_center_joint_l2" type="fixed">
    <origin rpy="0 0 0" xyz="0 0.325 0"/>
    <parent link="thorax"/>
    <child link="leg_center_l2"/>
  </joint>
  <link name="leg_center_l2">
    <inertial>
      <origin rpy="1.5707963267948966 0 1.5707963267948966" xyz="0 0 0"/>
      <mass value="0.001"/>
      <inertia ixx="4.166666666666667e-07" ixy="0.0" ixz="0.0" iyy="4.166666666666667e-07" iyz="0.0" izz="4.166666666666667e-07"/>
    </inertial>
  </link>
  <joint name="coxa_joint_l2" type="revolute">
    <origin rpy="0 0 1.5707963267948966" xyz="0 0 0"/>
    <parent link="leg_center_l2"/>
    <child link="coxa_l2"/>
    <axis xyz="0 0 -1"/>
    <limit effort="10000" lower="-1.5" upper="1.5" velocity="100"/>
  </joint>
  <transmission name="coxa_tran_l2">
    <type>transmission_interface/SimpleTransmission</type>
    <joint name="coxa_joint_l2">
      <hardwareInterface>hardware_interface/EffortJointInterface</hardwareInterface>
    </joint>
    <actuator name="coxa_motor_l2">
      <hardwareInterface>hardware_interface/EffortJointInterface</hardwareInterface>
      <mechanicalReduction>1</mechanicalReduction>
    </actuator>
  </transmission>
  <link name="coxa_l2">
    <visual>
      <origin rpy="0 0 0" xyz="0.04 0.025 0"/>
      <geometry>
        <box size="0.16499999999999998 0.16499999999999998 0.16499999999999998"/>
      </geometry>
      <material name="">
        <color rgba="0.7 0.7 0 1"/>
      </material>
    </visual>
    <collision>
      <origin rpy="0 0 0" xyz="0.04 0.025 0"/>
      <geometry>
        <box size="0.16499999999999998 0.16499999999999998 0.16499999999999998"/>
      </geometry>
      <material name="">
        <color rgba="0.7 0.7 0 1"/>
      </material>
    </collision>
    <inertial>
      <origin rpy="1.5707963267948966 0 1.5707963267948966" xyz="0 0 0"/>
      <mass value="0.01"/>
      <inertia ixx="4.537499999999999e-05" ixy="0.0" ixz="0.0" iyy="4.537499999999999e-05" iyz="0.0" izz="4.537499999999999e-05"/>
    </inertial>
  </link>
  <joint name="femur_joint_l2" type="revolute">
    <origin rpy="-1.5707963267948966 0 0" xyz="0.05 0 -0.05"/>
    <parent link="coxa_l2"/>
    <child link="femur_l2"/>
    <axis xyz="0 0 -1"/>
    <limit effort="10000" lower="-1.5" upper="1.5" velocity="100"/>
  </joint>
  <transmission name="femur_tran_l2">
    <type>transmission_interface/SimpleTransmission</type>
    <joint name="femur_joint_l2">
      <hardwareInterface>hardware_interface/EffortJointInterface</hardwareInterface>
    </joint>
    <actuator name="femur_motor_l2">
      <hardwareInterface>hardware_interface/EffortJointInterface</hardwareInterface>
      <mechanicalReduction>1</mechanicalReduction>
    </actuator>
  </transmission>
  <link name="femur_l2">
    <visual>
      <origin rpy="0 0 0" xyz="0.175 0 0"/>
      <geometry>
        <box size="0.35 0.075 0.02"/>
        <!-- <mesh filename="package://crab_description/meshes/femur_${side}.STL" /> -->
      </geometry>
      <material name="">
        <color rgba="0 0.7 0.7 1"/>
      </material>
    </visual>
    <collision>
      <origin rpy="0 0 0" xyz="0.175 0 0"/>
      <geometry>
        <box size="0.35 0.075 0.02"/>
        <!-- <mesh filename="package://crab_description/meshes/femur_${side}.STL" /> -->
      </geometry>
      <material name="">
        <color rgba="0 0.7 0.7 1"/>
      </material>
    </collision>
    <inertial>
      <origin rpy="1.5707963267948966 0 1.5707963267948966" xyz="0 0 0"/>
      <mass value="0.01"/>
      <inertia ixx="5.020833333333334e-06" ixy="0.0" ixz="0.0" iyy="0.00010677083333333332" iyz="0.0" izz="0.00010241666666666666"/>
    </inertial>
  </link>
  <joint name="tibia_joint_l2" type="revolute">
    <origin rpy="3.141592653589793 0 1.5707963267948966" xyz="0.32999999999999996 0 0"/>
    <parent link="femur_l2"/>
    <child link="tibia_l2"/>
    <axis xyz="0 0 1"/>
    <limit effort="10000" lower="-1.5" upper="1.5" velocity="100"/>
  </joint>
  <transmission name="tibia_tran_l2">
    <type>transmission_interface/SimpleTransmission</type>
    <joint name="tibia_joint_l2">
      <hardwareInterface>hardware_interface/EffortJointInterface</hardwareInterface>
    </joint>
    <actuator name="tibia_motor_l2">
      <hardwareInterface>hardware_interface/EffortJointInterface</hardwareInterface>
      <mechanicalReduction>1</mechanicalReduction>
    </actuator>
  </transmission>
  <link name="tibia_l2">
    <visual>
      <origin rpy="0 0 0.06" xyz="0.19 0 0.1"/>
      <geometry>
        <box size="0.45 0.1 0.025"/>
        <!-- <mesh filename="package://crab_description/meshes/tibia_${side}.STL" /> -->
      </geometry>
      <material name="">
        <color rgba="0.7 0 0.7 1"/>
      </material>
    </visual>
    <collision>
      <origin rpy="0 0 0.06" xyz="0.19 0 0.1"/>
      <geometry>
        <box size="0.45 0.1 0.025"/>
        <!-- <mesh filename="package://crab_description/meshes/tibia_${side}.STL" /> -->
      </geometry>
      <surface>
        <friction>
          <ode>
            <mu>10000.01</mu>
            <mu2>10000.01</mu2>
          </ode>
        </friction>
      </surface>
      <material name="">
        <color rgba="0.7 0 0.7 1"/>
      </material>
    </collision>
    <inertial>
      <origin rpy="1.5707963267948966 0 1.5707963267948966" xyz="0 0 0"/>
      <mass value="0.01"/>
      <inertia ixx="8.854166666666669e-06" ixy="0.0" ixz="0.0" iyy="0.00017708333333333337" iyz="0.0" izz="0.00016927083333333334"/>
    </inertial>
  </link>
  <joint name="tibia_foot_joint_l2" type="fixed">
    <origin rpy="0 0 0" xyz="0.117 0 0"/>
    <parent link="tibia_l2"/>
    <child link="tibia_foot_l2"/>
  </joint>
  <link name="tibia_foot_l2"/>
  <!-- Build leg -->
  <!-- joint to center of thorax -->
  <joint name="leg_center_joint_l3" type="fixed">
    <origin rpy="0 0 0" xyz="-0.3875 0.325 0"/>
    <parent link="thorax"/>
    <child link="leg_center_l3"/>
  </joint>
  <link name="leg_center_l3">
    <inertial>
      <origin rpy="1.5707963267948966 0 1.5707963267948966" xyz="0 0 0"/>
      <mass value="0.001"/>
      <inertia ixx="4.166666666666667e-07" ixy="0.0" ixz="0.0" iyy="4.166666666666667e-07" iyz="0.0" izz="4.166666666666667e-07"/>
    </inertial>
  </link>
  <joint name="coxa_joint_l3" type="revolute">
    <origin rpy="0 0 2.0943951023931953" xyz="0 0 0"/>
    <parent link="leg_center_l3"/>
    <child link="coxa_l3"/>
    <axis xyz="0 0 -1"/>
    <limit effort="10000" lower="-1.5" upper="1.5" velocity="100"/>
  </joint>
  <transmission name="coxa_tran_l3">
    <type>transmission_interface/SimpleTransmission</type>
    <joint name="coxa_joint_l3">
      <hardwareInterface>hardware_interface/EffortJointInterface</hardwareInterface>
    </joint>
    <actuator name="coxa_motor_l3">
      <hardwareInterface>hardware_interface/EffortJointInterface</hardwareInterface>
      <mechanicalReduction>1</mechanicalReduction>
    </actuator>
  </transmission>
  <link name="coxa_l3">
    <visual>
      <origin rpy="0 0 0" xyz="0.04 0.025 0"/>
      <geometry>
        <box size="0.16499999999999998 0.16499999999999998 0.16499999999999998"/>
      </geometry>
      <material name="">
        <color rgba="0.7 0.7 0 1"/>
      </material>
    </visual>
    <collision>
      <origin rpy="0 0 0" xyz="0.04 0.025 0"/>
      <geometry>
        <box size="0.16499999999999998 0.16499999999999998 0.16499999999999998"/>
      </geometry>
      <material name="">
        <color rgba="0.7 0.7 0 1"/>
      </material>
    </collision>
    <inertial>
      <origin rpy="1.5707963267948966 0 1.5707963267948966" xyz="0 0 0"/>
      <mass value="0.01"/>
      <inertia ixx="4.537499999999999e-05" ixy="0.0" ixz="0.0" iyy="4.537499999999999e-05" iyz="0.0" izz="4.537499999999999e-05"/>
    </inertial>
  </link>
  <joint name="femur_joint_l3" type="revolute">
    <origin rpy="-1.5707963267948966 0 0" xyz="0.05 0 -0.05"/>
    <parent link="coxa_l3"/>
    <child link="femur_l3"/>
    <axis xyz="0 0 -1"/>
    <limit effort="10000" lower="-1.5" upper="1.5" velocity="100"/>
  </joint>
  <transmission name="femur_tran_l3">
    <type>transmission_interface/SimpleTransmission</type>
    <joint name="femur_joint_l3">
      <hardwareInterface>hardware_interface/EffortJointInterface</hardwareInterface>
    </joint>
    <actuator name="femur_motor_l3">
      <hardwareInterface>hardware_interface/EffortJointInterface</hardwareInterface>
      <mechanicalReduction>1</mechanicalReduction>
    </actuator>
  </transmission>
  <link name="femur_l3">
    <visual>
      <origin rpy="0 0 0" xyz="0.175 0 0"/>
      <geometry>
        <box size="0.35 0.075 0.02"/>
        <!-- <mesh filename="package://crab_description/meshes/femur_${side}.STL" /> -->
      </geometry>
      <material name="">
        <color rgba="0 0.7 0.7 1"/>
      </material>
    </visual>
    <collision>
      <origin rpy="0 0 0" xyz="0.175 0 0"/>
      <geometry>
        <box size="0.35 0.075 0.02"/>
        <!-- <mesh filename="package://crab_description/meshes/femur_${side}.STL" /> -->
      </geometry>
      <material name="">
        <color rgba="0 0.7 0.7 1"/>
      </material>
    </collision>
    <inertial>
      <origin rpy="1.5707963267948966 0 1.5707963267948966" xyz="0 0 0"/>
      <mass value="0.01"/>
      <inertia ixx="5.020833333333334e-06" ixy="0.0" ixz="0.0" iyy="0.00010677083333333332" iyz="0.0" izz="0.00010241666666666666"/>
    </inertial>
  </link>
  <joint name="tibia_joint_l3" type="revolute">
    <origin rpy="3.141592653589793 0 1.5707963267948966" xyz="0.32999999999999996 0 0"/>
    <parent link="femur_l3"/>
    <child link="tibia_l3"/>
    <axis xyz="0 0 1"/>
    <limit effort="10000" lower="-1.5" upper="1.5" velocity="100"/>
  </joint>
  <transmission name="tibia_tran_l3">
    <type>transmission_interface/SimpleTransmission</type>
    <joint name="tibia_joint_l3">
      <hardwareInterface>hardware_interface/EffortJointInterface</hardwareInterface>
    </joint>
    <actuator name="tibia_motor_l3">
      <hardwareInterface>hardware_interface/EffortJointInterface</hardwareInterface>
      <mechanicalReduction>1</mechanicalReduction>
    </actuator>
  </transmission>
  <link name="tibia_l3">
    <visual>
      <origin rpy="0 0 0.06" xyz="0.19 0 0.1"/>
      <geometry>
        <box size="0.45 0.1 0.025"/>
        <!-- <mesh filename="package://crab_description/meshes/tibia_${side}.STL" /> -->
      </geometry>
      <material name="">
        <color rgba="0.7 0 0.7 1"/>
      </material>
    </visual>
    <collision>
      <origin rpy="0 0 0.06" xyz="0.19 0 0.1"/>
      <geometry>
        <box size="0.45 0.1 0.025"/>
        <!-- <mesh filename="package://crab_description/meshes/tibia_${side}.STL" /> -->
      </geometry>
      <surface>
        <friction>
          <ode>
            <mu>10000.01</mu>
            <mu2>10000.01</mu2>
          </ode>
        </friction>
      </surface>
      <material name="">
        <color rgba="0.7 0 0.7 1"/>
      </material>
    </collision>
    <inertial>
      <origin rpy="1.5707963267948966 0 1.5707963267948966" xyz="0 0 0"/>
      <mass value="0.01"/>
      <inertia ixx="8.854166666666669e-06" ixy="0.0" ixz="0.0" iyy="0.00017708333333333337" iyz="0.0" izz="0.00016927083333333334"/>
    </inertial>
  </link>
  <joint name="tibia_foot_joint_l3" type="fixed">
    <origin rpy="0 0 0" xyz="0.117 0 0"/>
    <parent link="tibia_l3"/>
    <child link="tibia_foot_l3"/>
  </joint>
  <link name="tibia_foot_l3"/>
  <gazebo>
    <plugin filename="libgazebo_ros_control.so" name="gazebo_ros_control">
      <robotNamespace>/hexapod</robotNamespace>
    </plugin>
    <self_collide>1</self_collide>
  </gazebo>
  <!-- Contact Sensor -->
  <gazebo reference="base_link">
    <material>Gazebo/Blue</material>
    <kp>1000.0</kp>
    <kd>1000.0</kd>
    <mu1>1000000.0</mu1>
    <mu2>1000000.0</mu2>
    <sensor name="contactsensor_sensor" type="contact">
      <always_on>true</always_on>
      <contact>
        <collision>contactsensor_sensor</collision>
      </contact>
      <plugin filename="libgazebo_ros_bumper.so" name="bumper0_plugin">
        <bumperTopicName>contactsensor_state</bumperTopicName>
        <frameName>contactsensor_link</frameName>
      </plugin>
    </sensor>
  </gazebo>
  <!-- ODOM sensor -->
  <gazebo>
    <plugin filename="libgazebo_ros_p3d.so" name="p3d_base_controller">
      <alwaysOn>true</alwaysOn>
      <!--<updateRate>50.0</updateRate>-->
      <bodyName>base_link</bodyName>
      <topicName>odom</topicName>
      <gaussianNoise>0.01</gaussianNoise>
      <frameName>world</frameName>
      <xyzOffsets>0 0 0</xyzOffsets>
      <rpyOffsets>0 0 0</rpyOffsets>
    </plugin>
  </gazebo>
  <!-- IMU sensor -->
  <gazebo>
    <plugin filename="libgazebo_ros_imu.so" name="gazebo_ros_imu_controller">
      <robotNamespace>/hexapod</robotNamespace>
      <topicName>imu/data</topicName>
      <serviceName>imu/service</serviceName>
      <bodyName>base_link</bodyName>
      <gaussianNoise>0</gaussianNoise>
      <rpyOffsets>0 0 0</rpyOffsets>
      <!--<updateRate>50.0</updateRate>-->
      <alwaysOn>true</alwaysOn>
      <gaussianNoise>0</gaussianNoise>
    </plugin>
  </gazebo>
  <gazebo reference="femur_l1">
    <mu1>10000.9</mu1>
    <mu2>10000.9</mu2>
    <minDepth>0.001</minDepth>
    <kp>100000000</kp>
    <kd>1</kd>
  </gazebo>
  <gazebo reference="femur_l2">
    <mu1>10000.9</mu1>
    <mu2>10000.9</mu2>
    <minDepth>0.001</minDepth>
    <kp>100000000</kp>
    <kd>1</kd>
  </gazebo>
  <gazebo reference="femur_l3">
    <mu1>10000.9</mu1>
    <mu2>10000.9</mu2>
    <minDepth>0.001</minDepth>
    <kp>100000000</kp>
    <kd>1</kd>
  </gazebo>
  <gazebo reference="femur_r1">
    <mu1>10000.9</mu1>
    <mu2>10000.9</mu2>
    <minDepth>0.001</minDepth>
    <kp>100000000</kp>
    <kd>1</kd>
  </gazebo>
  <gazebo reference="femur_r2">
    <mu1>10000.9</mu1>
    <mu2>10000.9</mu2>
    <minDepth>0.001</minDepth>
    <kp>100000000</kp>
    <kd>1</kd>
  </gazebo>
  <gazebo reference="femur_r3">
    <mu1>10000.9</mu1>
    <mu2>10000.9</mu2>
    <minDepth>0.001</minDepth>
    <kp>100000000</kp>
    <kd>1</kd>
  </gazebo>
</robot>
