<sdf version='1.7'>
  <model name='hexapod'>
    <link name='base_link'>
      <inertial>
        <pose>0 0 0 0 -0 0</pose>
        <mass>0.036</mass>
        <inertia>
          <ixx>0.00226437</ixx>
          <ixy>-1.35525e-19</ixy>
          <ixz>-2.63359e-19</ixz>
          <iyy>0.00178594</iyy>
          <iyz>6.8585e-35</iyz>
          <izz>0.00379469</izz>
        </inertia>
      </inertial>
      <collision name='base_link_collision'>
        <pose>0 0 0 0 -0 0</pose>
        <geometry>
          <box>
            <size>0.775 0.65 0.225</size>
          </box>
        </geometry>
        <surface>
          <contact>
            <ode>
              <kp>1000</kp>
              <kd>1000</kd>
            </ode>
          </contact>
          <friction>
            <ode>
              <mu>1e+06</mu>
              <mu2>1e+06</mu2>
            </ode>
          </friction>
        </surface>
      </collision>
      <collision name='base_link_fixed_joint_lump__thorax_collision_1'>
        <pose>0 0 0 0 -0 0</pose>
        <geometry>
          <box>
            <size>0.775 0.65 0.225</size>
          </box>
        </geometry>
      </collision>
      <visual name='base_link_fixed_joint_lump__thorax_visual'>
        <pose>0 0 0 0 -0 0</pose>
        <geometry>
          <box>
            <size>0.775 0.65 0.225</size>
          </box>
        </geometry>
      </visual>
      <sensor name='contactsensor_sensor' type='contact'>
        <always_on>1</always_on>
        <contact>
          <collision>contactsensor_sensor</collision>
          <topic>__default_topic__</topic>
        </contact>
        <plugin name='bumper0_plugin' filename='libgazebo_ros_bumper.so'>
          <bumperTopicName>contactsensor_state</bumperTopicName>
          <frameName>contactsensor_link</frameName>
        </plugin>
      </sensor>
    </link>
    <joint name='coxa_joint_l1' type='revolute'>
      <pose relative_to='base_link'>0.3875 0.325 0 0 -0 1.0472</pose>
      <parent>base_link</parent>
      <child>coxa_l1</child>
      <axis>
        <xyz>0 0 -1</xyz>
        <limit>
          <lower>-1.5</lower>
          <upper>1.5</upper>
          <effort>10000</effort>
          <velocity>100</velocity>
        </limit>
        <dynamics>
          <spring_reference>0</spring_reference>
          <spring_stiffness>0</spring_stiffness>
        </dynamics>
      </axis>
    </joint>
    <link name='coxa_l1'>
      <pose relative_to='coxa_joint_l1'>0 0 0 0 -0 0</pose>
      <inertial>
        <pose>0 0 0 1.5708 -0 1.5708</pose>
        <mass>0.01</mass>
        <inertia>
          <ixx>4.5375e-05</ixx>
          <ixy>0</ixy>
          <ixz>0</ixz>
          <iyy>4.5375e-05</iyy>
          <iyz>0</iyz>
          <izz>4.5375e-05</izz>
        </inertia>
      </inertial>
      <collision name='coxa_l1_collision'>
        <pose>0.04 0.025 0 0 -0 0</pose>
        <geometry>
          <box>
            <size>0.165 0.165 0.165</size>
          </box>
        </geometry>
      </collision>
      <visual name='coxa_l1_visual'>
        <pose>0.04 0.025 0 0 -0 0</pose>
        <geometry>
          <box>
            <size>0.165 0.165 0.165</size>
          </box>
        </geometry>
      </visual>
    </link>
    <joint name='femur_joint_l1' type='revolute'>
      <pose relative_to='coxa_l1'>0.05 0 -0.05 -1.5708 0 0</pose>
      <parent>coxa_l1</parent>
      <child>femur_l1</child>
      <axis>
        <xyz>0 0 -1</xyz>
        <limit>
          <lower>-1.5</lower>
          <upper>1.5</upper>
          <effort>10000</effort>
          <velocity>100</velocity>
        </limit>
        <dynamics>
          <spring_reference>0</spring_reference>
          <spring_stiffness>0</spring_stiffness>
        </dynamics>
      </axis>
    </joint>
    <link name='femur_l1'>
      <pose relative_to='femur_joint_l1'>0 0 0 0 -0 0</pose>
      <inertial>
        <pose>0 0 0 1.5708 -0 1.5708</pose>
        <mass>0.01</mass>
        <inertia>
          <ixx>5.02083e-06</ixx>
          <ixy>0</ixy>
          <ixz>0</ixz>
          <iyy>0.000106771</iyy>
          <iyz>0</iyz>
          <izz>0.000102417</izz>
        </inertia>
      </inertial>
      <collision name='femur_l1_collision'>
        <pose>0.175 0 0 0 -0 0</pose>
        <geometry>
          <box>
            <size>0.35 0.075 0.02</size>
          </box>
        </geometry>
        <surface>
          <contact>
            <ode>
              <kp>1e+08</kp>
              <kd>1</kd>
              <min_depth>0.001</min_depth>
            </ode>
          </contact>
          <friction>
            <ode>
              <mu>10000.9</mu>
              <mu2>10000.9</mu2>
            </ode>
          </friction>
        </surface>
      </collision>
      <visual name='femur_l1_visual'>
        <pose>0.175 0 0 0 -0 0</pose>
        <geometry>
          <box>
            <size>0.35 0.075 0.02</size>
          </box>
        </geometry>
      </visual>
    </link>
    <joint name='tibia_joint_l1' type='revolute'>
      <pose relative_to='femur_l1'>0.33 0 0 3.14159 -0 1.5708</pose>
      <parent>femur_l1</parent>
      <child>tibia_l1</child>
      <axis>
        <xyz>0 0 1</xyz>
        <limit>
          <lower>-1.5</lower>
          <upper>1.5</upper>
          <effort>10000</effort>
          <velocity>100</velocity>
        </limit>
        <dynamics>
          <spring_reference>0</spring_reference>
          <spring_stiffness>0</spring_stiffness>
        </dynamics>
      </axis>
    </joint>
    <link name='tibia_l1'>
      <pose relative_to='tibia_joint_l1'>0 0 0 0 -0 0</pose>
      <inertial>
        <pose>0 0 0 1.5708 -0 1.5708</pose>
        <mass>0.01</mass>
        <inertia>
          <ixx>8.85417e-06</ixx>
          <ixy>0</ixy>
          <ixz>0</ixz>
          <iyy>0.000177083</iyy>
          <iyz>0</iyz>
          <izz>0.000169271</izz>
        </inertia>
      </inertial>
      <collision name='tibia_l1_collision'>
        <pose>0.19 0 0.1 0 -0 0.06</pose>
        <geometry>
          <box>
            <size>0.45 0.1 0.025</size>
          </box>
        </geometry>
      </collision>
      <visual name='tibia_l1_visual'>
        <pose>0.19 0 0.1 0 -0 0.06</pose>
        <geometry>
          <box>
            <size>0.45 0.1 0.025</size>
          </box>
        </geometry>
      </visual>
    </link>
    <joint name='coxa_joint_l2' type='revolute'>
      <pose relative_to='base_link'>0 0.325 0 0 -0 1.5708</pose>
      <parent>base_link</parent>
      <child>coxa_l2</child>
      <axis>
        <xyz>0 0 -1</xyz>
        <limit>
          <lower>-1.5</lower>
          <upper>1.5</upper>
          <effort>10000</effort>
          <velocity>100</velocity>
        </limit>
        <dynamics>
          <spring_reference>0</spring_reference>
          <spring_stiffness>0</spring_stiffness>
        </dynamics>
      </axis>
    </joint>
    <link name='coxa_l2'>
      <pose relative_to='coxa_joint_l2'>0 0 0 0 -0 0</pose>
      <inertial>
        <pose>0 0 0 1.5708 -0 1.5708</pose>
        <mass>0.01</mass>
        <inertia>
          <ixx>4.5375e-05</ixx>
          <ixy>0</ixy>
          <ixz>0</ixz>
          <iyy>4.5375e-05</iyy>
          <iyz>0</iyz>
          <izz>4.5375e-05</izz>
        </inertia>
      </inertial>
      <collision name='coxa_l2_collision'>
        <pose>0.04 0.025 0 0 -0 0</pose>
        <geometry>
          <box>
            <size>0.165 0.165 0.165</size>
          </box>
        </geometry>
      </collision>
      <visual name='coxa_l2_visual'>
        <pose>0.04 0.025 0 0 -0 0</pose>
        <geometry>
          <box>
            <size>0.165 0.165 0.165</size>
          </box>
        </geometry>
      </visual>
    </link>
    <joint name='femur_joint_l2' type='revolute'>
      <pose relative_to='coxa_l2'>0.05 0 -0.05 -1.5708 0 0</pose>
      <parent>coxa_l2</parent>
      <child>femur_l2</child>
      <axis>
        <xyz>0 0 -1</xyz>
        <limit>
          <lower>-1.5</lower>
          <upper>1.5</upper>
          <effort>10000</effort>
          <velocity>100</velocity>
        </limit>
        <dynamics>
          <spring_reference>0</spring_reference>
          <spring_stiffness>0</spring_stiffness>
        </dynamics>
      </axis>
    </joint>
    <link name='femur_l2'>
      <pose relative_to='femur_joint_l2'>0 0 0 0 -0 0</pose>
      <inertial>
        <pose>0 0 0 1.5708 -0 1.5708</pose>
        <mass>0.01</mass>
        <inertia>
          <ixx>5.02083e-06</ixx>
          <ixy>0</ixy>
          <ixz>0</ixz>
          <iyy>0.000106771</iyy>
          <iyz>0</iyz>
          <izz>0.000102417</izz>
        </inertia>
      </inertial>
      <collision name='femur_l2_collision'>
        <pose>0.175 0 0 0 -0 0</pose>
        <geometry>
          <box>
            <size>0.35 0.075 0.02</size>
          </box>
        </geometry>
        <surface>
          <contact>
            <ode>
              <kp>1e+08</kp>
              <kd>1</kd>
              <min_depth>0.001</min_depth>
            </ode>
          </contact>
          <friction>
            <ode>
              <mu>10000.9</mu>
              <mu2>10000.9</mu2>
            </ode>
          </friction>
        </surface>
      </collision>
      <visual name='femur_l2_visual'>
        <pose>0.175 0 0 0 -0 0</pose>
        <geometry>
          <box>
            <size>0.35 0.075 0.02</size>
          </box>
        </geometry>
      </visual>
    </link>
    <joint name='tibia_joint_l2' type='revolute'>
      <pose relative_to='femur_l2'>0.33 0 0 3.14159 -0 1.5708</pose>
      <parent>femur_l2</parent>
      <child>tibia_l2</child>
      <axis>
        <xyz>0 0 1</xyz>
        <limit>
          <lower>-1.5</lower>
          <upper>1.5</upper>
          <effort>10000</effort>
          <velocity>100</velocity>
        </limit>
        <dynamics>
          <spring_reference>0</spring_reference>
          <spring_stiffness>0</spring_stiffness>
        </dynamics>
      </axis>
    </joint>
    <link name='tibia_l2'>
      <pose relative_to='tibia_joint_l2'>0 0 0 0 -0 0</pose>
      <inertial>
        <pose>0 0 0 1.5708 -0 1.5708</pose>
        <mass>0.01</mass>
        <inertia>
          <ixx>8.85417e-06</ixx>
          <ixy>0</ixy>
          <ixz>0</ixz>
          <iyy>0.000177083</iyy>
          <iyz>0</iyz>
          <izz>0.000169271</izz>
        </inertia>
      </inertial>
      <collision name='tibia_l2_collision'>
        <pose>0.19 0 0.1 0 -0 0.06</pose>
        <geometry>
          <box>
            <size>0.45 0.1 0.025</size>
          </box>
        </geometry>
      </collision>
      <visual name='tibia_l2_visual'>
        <pose>0.19 0 0.1 0 -0 0.06</pose>
        <geometry>
          <box>
            <size>0.45 0.1 0.025</size>
          </box>
        </geometry>
      </visual>
    </link>
    <joint name='coxa_joint_l3' type='revolute'>
      <pose relative_to='base_link'>-0.3875 0.325 0 0 -0 2.0944</pose>
      <parent>base_link</parent>
      <child>coxa_l3</child>
      <axis>
        <xyz>0 0 -1</xyz>
        <limit>
          <lower>-1.5</lower>
          <upper>1.5</upper>
          <effort>10000</effort>
          <velocity>100</velocity>
        </limit>
        <dynamics>
          <spring_reference>0</spring_reference>
          <spring_stiffness>0</spring_stiffness>
        </dynamics>
      </axis>
    </joint>
    <link name='coxa_l3'>
      <pose relative_to='coxa_joint_l3'>0 0 0 0 -0 0</pose>
      <inertial>
        <pose>0 0 0 1.5708 -0 1.5708</pose>
        <mass>0.01</mass>
        <inertia>
          <ixx>4.5375e-05</ixx>
          <ixy>0</ixy>
          <ixz>0</ixz>
          <iyy>4.5375e-05</iyy>
          <iyz>0</iyz>
          <izz>4.5375e-05</izz>
        </inertia>
      </inertial>
      <collision name='coxa_l3_collision'>
        <pose>0.04 0.025 0 0 -0 0</pose>
        <geometry>
          <box>
            <size>0.165 0.165 0.165</size>
          </box>
        </geometry>
      </collision>
      <visual name='coxa_l3_visual'>
        <pose>0.04 0.025 0 0 -0 0</pose>
        <geometry>
          <box>
            <size>0.165 0.165 0.165</size>
          </box>
        </geometry>
      </visual>
    </link>
    <joint name='femur_joint_l3' type='revolute'>
      <pose relative_to='coxa_l3'>0.05 0 -0.05 -1.5708 0 0</pose>
      <parent>coxa_l3</parent>
      <child>femur_l3</child>
      <axis>
        <xyz>0 0 -1</xyz>
        <limit>
          <lower>-1.5</lower>
          <upper>1.5</upper>
          <effort>10000</effort>
          <velocity>100</velocity>
        </limit>
        <dynamics>
          <spring_reference>0</spring_reference>
          <spring_stiffness>0</spring_stiffness>
        </dynamics>
      </axis>
    </joint>
    <link name='femur_l3'>
      <pose relative_to='femur_joint_l3'>0 0 0 0 -0 0</pose>
      <inertial>
        <pose>0 0 0 1.5708 -0 1.5708</pose>
        <mass>0.01</mass>
        <inertia>
          <ixx>5.02083e-06</ixx>
          <ixy>0</ixy>
          <ixz>0</ixz>
          <iyy>0.000106771</iyy>
          <iyz>0</iyz>
          <izz>0.000102417</izz>
        </inertia>
      </inertial>
      <collision name='femur_l3_collision'>
        <pose>0.175 0 0 0 -0 0</pose>
        <geometry>
          <box>
            <size>0.35 0.075 0.02</size>
          </box>
        </geometry>
        <surface>
          <contact>
            <ode>
              <kp>1e+08</kp>
              <kd>1</kd>
              <min_depth>0.001</min_depth>
            </ode>
          </contact>
          <friction>
            <ode>
              <mu>10000.9</mu>
              <mu2>10000.9</mu2>
            </ode>
          </friction>
        </surface>
      </collision>
      <visual name='femur_l3_visual'>
        <pose>0.175 0 0 0 -0 0</pose>
        <geometry>
          <box>
            <size>0.35 0.075 0.02</size>
          </box>
        </geometry>
      </visual>
    </link>
    <joint name='tibia_joint_l3' type='revolute'>
      <pose relative_to='femur_l3'>0.33 0 0 3.14159 -0 1.5708</pose>
      <parent>femur_l3</parent>
      <child>tibia_l3</child>
      <axis>
        <xyz>0 0 1</xyz>
        <limit>
          <lower>-1.5</lower>
          <upper>1.5</upper>
          <effort>10000</effort>
          <velocity>100</velocity>
        </limit>
        <dynamics>
          <spring_reference>0</spring_reference>
          <spring_stiffness>0</spring_stiffness>
        </dynamics>
      </axis>
    </joint>
    <link name='tibia_l3'>
      <pose relative_to='tibia_joint_l3'>0 0 0 0 -0 0</pose>
      <inertial>
        <pose>0 0 0 1.5708 -0 1.5708</pose>
        <mass>0.01</mass>
        <inertia>
          <ixx>8.85417e-06</ixx>
          <ixy>0</ixy>
          <ixz>0</ixz>
          <iyy>0.000177083</iyy>
          <iyz>0</iyz>
          <izz>0.000169271</izz>
        </inertia>
      </inertial>
      <collision name='tibia_l3_collision'>
        <pose>0.19 0 0.1 0 -0 0.06</pose>
        <geometry>
          <box>
            <size>0.45 0.1 0.025</size>
          </box>
        </geometry>
      </collision>
      <visual name='tibia_l3_visual'>
        <pose>0.19 0 0.1 0 -0 0.06</pose>
        <geometry>
          <box>
            <size>0.45 0.1 0.025</size>
          </box>
        </geometry>
      </visual>
    </link>
    <joint name='coxa_joint_r1' type='revolute'>
      <pose relative_to='base_link'>0.3875 -0.325 0 0 0 -1.0472</pose>
      <parent>base_link</parent>
      <child>coxa_r1</child>
      <axis>
        <xyz>0 0 -1</xyz>
        <limit>
          <lower>-1.5</lower>
          <upper>1.5</upper>
          <effort>10000</effort>
          <velocity>100</velocity>
        </limit>
        <dynamics>
          <spring_reference>0</spring_reference>
          <spring_stiffness>0</spring_stiffness>
        </dynamics>
      </axis>
    </joint>
    <link name='coxa_r1'>
      <pose relative_to='coxa_joint_r1'>0 0 0 0 -0 0</pose>
      <inertial>
        <pose>0 0 0 1.5708 -0 1.5708</pose>
        <mass>0.01</mass>
        <inertia>
          <ixx>4.5375e-05</ixx>
          <ixy>0</ixy>
          <ixz>0</ixz>
          <iyy>4.5375e-05</iyy>
          <iyz>0</iyz>
          <izz>4.5375e-05</izz>
        </inertia>
      </inertial>
      <collision name='coxa_r1_collision'>
        <pose>0.04 -0.025 0 0 -0 0</pose>
        <geometry>
          <box>
            <size>0.165 0.165 0.165</size>
          </box>
        </geometry>
      </collision>
      <visual name='coxa_r1_visual'>
        <pose>0.04 -0.025 0 0 -0 0</pose>
        <geometry>
          <box>
            <size>0.165 0.165 0.165</size>
          </box>
        </geometry>
      </visual>
    </link>
    <joint name='femur_joint_r1' type='revolute'>
      <pose relative_to='coxa_r1'>0.05 0 -0.05 -1.5708 0 0</pose>
      <parent>coxa_r1</parent>
      <child>femur_r1</child>
      <axis>
        <xyz>0 0 -1</xyz>
        <limit>
          <lower>-1.5</lower>
          <upper>1.5</upper>
          <effort>10000</effort>
          <velocity>100</velocity>
        </limit>
        <dynamics>
          <spring_reference>0</spring_reference>
          <spring_stiffness>0</spring_stiffness>
        </dynamics>
      </axis>
    </joint>
    <link name='femur_r1'>
      <pose relative_to='femur_joint_r1'>0 0 0 0 -0 0</pose>
      <inertial>
        <pose>0 0 0 1.5708 -0 1.5708</pose>
        <mass>0.01</mass>
        <inertia>
          <ixx>5.02083e-06</ixx>
          <ixy>0</ixy>
          <ixz>0</ixz>
          <iyy>0.000106771</iyy>
          <iyz>0</iyz>
          <izz>0.000102417</izz>
        </inertia>
      </inertial>
      <collision name='femur_r1_collision'>
        <pose>0.175 0 0 0 -0 0</pose>
        <geometry>
          <box>
            <size>0.35 0.075 0.02</size>
          </box>
        </geometry>
        <surface>
          <contact>
            <ode>
              <kp>1e+08</kp>
              <kd>1</kd>
              <min_depth>0.001</min_depth>
            </ode>
          </contact>
          <friction>
            <ode>
              <mu>10000.9</mu>
              <mu2>10000.9</mu2>
            </ode>
          </friction>
        </surface>
      </collision>
      <visual name='femur_r1_visual'>
        <pose>0.175 0 0 0 -0 0</pose>
        <geometry>
          <box>
            <size>0.35 0.075 0.02</size>
          </box>
        </geometry>
      </visual>
    </link>
    <joint name='tibia_joint_r1' type='revolute'>
      <pose relative_to='femur_r1'>0.33 0 0 3.14159 -0 1.5708</pose>
      <parent>femur_r1</parent>
      <child>tibia_r1</child>
      <axis>
        <xyz>0 0 1</xyz>
        <limit>
          <lower>-1.5</lower>
          <upper>1.5</upper>
          <effort>10000</effort>
          <velocity>100</velocity>
        </limit>
        <dynamics>
          <spring_reference>0</spring_reference>
          <spring_stiffness>0</spring_stiffness>
        </dynamics>
      </axis>
    </joint>
    <link name='tibia_r1'>
      <pose relative_to='tibia_joint_r1'>0 0 0 0 -0 0</pose>
      <inertial>
        <pose>0 0 0 1.5708 -0 1.5708</pose>
        <mass>0.01</mass>
        <inertia>
          <ixx>8.85417e-06</ixx>
          <ixy>0</ixy>
          <ixz>0</ixz>
          <iyy>0.000177083</iyy>
          <iyz>0</iyz>
          <izz>0.000169271</izz>
        </inertia>
      </inertial>
      <collision name='tibia_r1_collision'>
        <pose>0.19 0 0.1 0 -0 0.06</pose>
        <geometry>
          <box>
            <size>0.45 0.1 0.025</size>
          </box>
        </geometry>
      </collision>
      <visual name='tibia_r1_visual'>
        <pose>0.19 0 0.1 0 -0 0.06</pose>
        <geometry>
          <box>
            <size>0.45 0.1 0.025</size>
          </box>
        </geometry>
      </visual>
    </link>
    <joint name='coxa_joint_r2' type='revolute'>
      <pose relative_to='base_link'>0 -0.325 0 0 0 -1.5708</pose>
      <parent>base_link</parent>
      <child>coxa_r2</child>
      <axis>
        <xyz>0 0 -1</xyz>
        <limit>
          <lower>-1.5</lower>
          <upper>1.5</upper>
          <effort>10000</effort>
          <velocity>100</velocity>
        </limit>
        <dynamics>
          <spring_reference>0</spring_reference>
          <spring_stiffness>0</spring_stiffness>
        </dynamics>
      </axis>
    </joint>
    <link name='coxa_r2'>
      <pose relative_to='coxa_joint_r2'>0 0 0 0 -0 0</pose>
      <inertial>
        <pose>0 0 0 1.5708 -0 1.5708</pose>
        <mass>0.01</mass>
        <inertia>
          <ixx>4.5375e-05</ixx>
          <ixy>0</ixy>
          <ixz>0</ixz>
          <iyy>4.5375e-05</iyy>
          <iyz>0</iyz>
          <izz>4.5375e-05</izz>
        </inertia>
      </inertial>
      <collision name='coxa_r2_collision'>
        <pose>0.04 -0.025 0 0 -0 0</pose>
        <geometry>
          <box>
            <size>0.165 0.165 0.165</size>
          </box>
        </geometry>
      </collision>
      <visual name='coxa_r2_visual'>
        <pose>0.04 -0.025 0 0 -0 0</pose>
        <geometry>
          <box>
            <size>0.165 0.165 0.165</size>
          </box>
        </geometry>
      </visual>
    </link>
    <joint name='femur_joint_r2' type='revolute'>
      <pose relative_to='coxa_r2'>0.05 0 -0.05 -1.5708 0 0</pose>
      <parent>coxa_r2</parent>
      <child>femur_r2</child>
      <axis>
        <xyz>0 0 -1</xyz>
        <limit>
          <lower>-1.5</lower>
          <upper>1.5</upper>
          <effort>10000</effort>
          <velocity>100</velocity>
        </limit>
        <dynamics>
          <spring_reference>0</spring_reference>
          <spring_stiffness>0</spring_stiffness>
        </dynamics>
      </axis>
    </joint>
    <link name='femur_r2'>
      <pose relative_to='femur_joint_r2'>0 0 0 0 -0 0</pose>
      <inertial>
        <pose>0 0 0 1.5708 -0 1.5708</pose>
        <mass>0.01</mass>
        <inertia>
          <ixx>5.02083e-06</ixx>
          <ixy>0</ixy>
          <ixz>0</ixz>
          <iyy>0.000106771</iyy>
          <iyz>0</iyz>
          <izz>0.000102417</izz>
        </inertia>
      </inertial>
      <collision name='femur_r2_collision'>
        <pose>0.175 0 0 0 -0 0</pose>
        <geometry>
          <box>
            <size>0.35 0.075 0.02</size>
          </box>
        </geometry>
        <surface>
          <contact>
            <ode>
              <kp>1e+08</kp>
              <kd>1</kd>
              <min_depth>0.001</min_depth>
            </ode>
          </contact>
          <friction>
            <ode>
              <mu>10000.9</mu>
              <mu2>10000.9</mu2>
            </ode>
          </friction>
        </surface>
      </collision>
      <visual name='femur_r2_visual'>
        <pose>0.175 0 0 0 -0 0</pose>
        <geometry>
          <box>
            <size>0.35 0.075 0.02</size>
          </box>
        </geometry>
      </visual>
    </link>
    <joint name='tibia_joint_r2' type='revolute'>
      <pose relative_to='femur_r2'>0.33 0 0 3.14159 -0 1.5708</pose>
      <parent>femur_r2</parent>
      <child>tibia_r2</child>
      <axis>
        <xyz>0 0 1</xyz>
        <limit>
          <lower>-1.5</lower>
          <upper>1.5</upper>
          <effort>10000</effort>
          <velocity>100</velocity>
        </limit>
        <dynamics>
          <spring_reference>0</spring_reference>
          <spring_stiffness>0</spring_stiffness>
        </dynamics>
      </axis>
    </joint>
    <link name='tibia_r2'>
      <pose relative_to='tibia_joint_r2'>0 0 0 0 -0 0</pose>
      <inertial>
        <pose>0 0 0 1.5708 -0 1.5708</pose>
        <mass>0.01</mass>
        <inertia>
          <ixx>8.85417e-06</ixx>
          <ixy>0</ixy>
          <ixz>0</ixz>
          <iyy>0.000177083</iyy>
          <iyz>0</iyz>
          <izz>0.000169271</izz>
        </inertia>
      </inertial>
      <collision name='tibia_r2_collision'>
        <pose>0.19 0 0.1 0 -0 0.06</pose>
        <geometry>
          <box>
            <size>0.45 0.1 0.025</size>
          </box>
        </geometry>
      </collision>
      <visual name='tibia_r2_visual'>
        <pose>0.19 0 0.1 0 -0 0.06</pose>
        <geometry>
          <box>
            <size>0.45 0.1 0.025</size>
          </box>
        </geometry>
      </visual>
    </link>
    <joint name='coxa_joint_r3' type='revolute'>
      <pose relative_to='base_link'>-0.3875 -0.325 0 0 0 -2.0944</pose>
      <parent>base_link</parent>
      <child>coxa_r3</child>
      <axis>
        <xyz>0 0 -1</xyz>
        <limit>
          <lower>-1.5</lower>
          <upper>1.5</upper>
          <effort>10000</effort>
          <velocity>100</velocity>
        </limit>
        <dynamics>
          <spring_reference>0</spring_reference>
          <spring_stiffness>0</spring_stiffness>
        </dynamics>
      </axis>
    </joint>
    <link name='coxa_r3'>
      <pose relative_to='coxa_joint_r3'>0 0 0 0 -0 0</pose>
      <inertial>
        <pose>0 0 0 1.5708 -0 1.5708</pose>
        <mass>0.01</mass>
        <inertia>
          <ixx>4.5375e-05</ixx>
          <ixy>0</ixy>
          <ixz>0</ixz>
          <iyy>4.5375e-05</iyy>
          <iyz>0</iyz>
          <izz>4.5375e-05</izz>
        </inertia>
      </inertial>
      <collision name='coxa_r3_collision'>
        <pose>0.04 -0.025 0 0 -0 0</pose>
        <geometry>
          <box>
            <size>0.165 0.165 0.165</size>
          </box>
        </geometry>
      </collision>
      <visual name='coxa_r3_visual'>
        <pose>0.04 -0.025 0 0 -0 0</pose>
        <geometry>
          <box>
            <size>0.165 0.165 0.165</size>
          </box>
        </geometry>
      </visual>
    </link>
    <joint name='femur_joint_r3' type='revolute'>
      <pose relative_to='coxa_r3'>0.05 0 -0.05 -1.5708 0 0</pose>
      <parent>coxa_r3</parent>
      <child>femur_r3</child>
      <axis>
        <xyz>0 0 -1</xyz>
        <limit>
          <lower>-1.5</lower>
          <upper>1.5</upper>
          <effort>10000</effort>
          <velocity>100</velocity>
        </limit>
        <dynamics>
          <spring_reference>0</spring_reference>
          <spring_stiffness>0</spring_stiffness>
        </dynamics>
      </axis>
    </joint>
    <link name='femur_r3'>
      <pose relative_to='femur_joint_r3'>0 0 0 0 -0 0</pose>
      <inertial>
        <pose>0 0 0 1.5708 -0 1.5708</pose>
        <mass>0.01</mass>
        <inertia>
          <ixx>5.02083e-06</ixx>
          <ixy>0</ixy>
          <ixz>0</ixz>
          <iyy>0.000106771</iyy>
          <iyz>0</iyz>
          <izz>0.000102417</izz>
        </inertia>
      </inertial>
      <collision name='femur_r3_collision'>
        <pose>0.175 0 0 0 -0 0</pose>
        <geometry>
          <box>
            <size>0.35 0.075 0.02</size>
          </box>
        </geometry>
        <surface>
          <contact>
            <ode>
              <kp>1e+08</kp>
              <kd>1</kd>
              <min_depth>0.001</min_depth>
            </ode>
          </contact>
          <friction>
            <ode>
              <mu>10000.9</mu>
              <mu2>10000.9</mu2>
            </ode>
          </friction>
        </surface>
      </collision>
      <visual name='femur_r3_visual'>
        <pose>0.175 0 0 0 -0 0</pose>
        <geometry>
          <box>
            <size>0.35 0.075 0.02</size>
          </box>
        </geometry>
      </visual>
    </link>
    <joint name='tibia_joint_r3' type='revolute'>
      <pose relative_to='femur_r3'>0.33 0 0 3.14159 -0 1.5708</pose>
      <parent>femur_r3</parent>
      <child>tibia_r3</child>
      <axis>
        <xyz>0 0 1</xyz>
        <limit>
          <lower>-1.5</lower>
          <upper>1.5</upper>
          <effort>10000</effort>
          <velocity>100</velocity>
        </limit>
        <dynamics>
          <spring_reference>0</spring_reference>
          <spring_stiffness>0</spring_stiffness>
        </dynamics>
      </axis>
    </joint>
    <link name='tibia_r3'>
      <pose relative_to='tibia_joint_r3'>0 0 0 0 -0 0</pose>
      <inertial>
        <pose>0 0 0 1.5708 -0 1.5708</pose>
        <mass>0.01</mass>
        <inertia>
          <ixx>8.85417e-06</ixx>
          <ixy>0</ixy>
          <ixz>0</ixz>
          <iyy>0.000177083</iyy>
          <iyz>0</iyz>
          <izz>0.000169271</izz>
        </inertia>
      </inertial>
      <collision name='tibia_r3_collision'>
        <pose>0.19 0 0.1 0 -0 0.06</pose>
        <geometry>
          <box>
            <size>0.45 0.1 0.025</size>
          </box>
        </geometry>
      </collision>
      <visual name='tibia_r3_visual'>
        <pose>0.19 0 0.1 0 -0 0.06</pose>
        <geometry>
          <box>
            <size>0.45 0.1 0.025</size>
          </box>
        </geometry>
      </visual>
    </link>
    <plugin name='gazebo_ros_control' filename='libgazebo_ros_control.so'>
      <robotNamespace>/hexapod</robotNamespace>
    </plugin>
    <self_collide>1</self_collide>
    <plugin name='p3d_base_controller' filename='libgazebo_ros_p3d.so'>
      <alwaysOn>1</alwaysOn>
      <bodyName>base_link</bodyName>
      <topicName>odom</topicName>
      <gaussianNoise>0.01</gaussianNoise>
      <frameName>world</frameName>
      <xyzOffsets>0 0 0</xyzOffsets>
      <rpyOffsets>0 0 0</rpyOffsets>
    </plugin>
    <static>0</static>
    <plugin name='gazebo_ros_imu_controller' filename='libgazebo_ros_imu.so'>
      <robotNamespace>/hexapod</robotNamespace>
      <topicName>imu/data</topicName>
      <serviceName>imu/service</serviceName>
      <bodyName>base_link</bodyName>
      <gaussianNoise>0</gaussianNoise>
      <rpyOffsets>0 0 0</rpyOffsets>
      <alwaysOn>1</alwaysOn>
      <gaussianNoise>0</gaussianNoise>
    </plugin>
  </model>
</sdf>
