<?xml version="1.0" ?>
<!-- =================================================================================== -->
<!-- |    This document was autogenerated by xacro from crab_model.xacro               | -->
<!-- |    EDITING THIS FILE BY HAND IS NOT RECOMMENDED                                 | -->
<!-- =================================================================================== -->
<robot name="crab">
  <!-- Properties -->
  <!-- <xacro:property name="base_width" value="0.31" />
	<xacro:property name="base_length" value="0.42" />
	<xacro:property name="base_height" value="0.18" /> -->
  <!-- Build the body frame -->
  <link name="base_link">
    <collision>
      <geometry>
        <box size="0.775 0.65 0.225"/>
      </geometry>
    </collision>
    <inertial>
      <origin rpy="1.5707963267948966 0 1.5707963267948966" xyz="0 0 0"/>
      <mass value="15"/>
      <inertia ixx="0.8140625000000001" ixy="0.0" ixz="0.0" iyy="1.2789062500000001" iyz="0.0" izz="0.59140625"/>
    </inertial>
  </link>
  <!-- Robot Footprint -->
  <!-- <link name="base_footprint"> -->
  <!-- <xacro:box_inertia m="0" w="0" d="0" h="0" /> -->
  <!-- </link> -->
  <joint name="base_joint" type="fixed">
    <parent link="base_link"/>
    <child link="thorax"/>
    <origin rpy="0 0 0" xyz="0 0 0"/>
  </joint>
  <link name="thorax">
    <visual>
      <origin rpy="0 0 0" xyz="0 0 0"/>
      <geometry>
        <box size="0.775 0.65 0.225"/>
        <!-- <mesh filename="package://crab_description/meshes/thorax.STL" /> -->
      </geometry>
      <material name="grey">
        <color rgba="0.5 0.5 0.5 1"/>
      </material>
    </visual>
    <collision>
      <origin rpy="0 0 0" xyz="0 0 0"/>
      <geometry>
        <box size="0.775 0.65 0.225"/>
        <!-- <mesh filename="package://crab_description/meshes/thorax.STL" /> -->
      </geometry>
      <material name="grey">
        <color rgba="0.5 0.5 0.5 1"/>
      </material>
    </collision>
    <inertial>
      <origin rpy="1.5707963267948966 0 1.5707963267948966" xyz="0 0 0"/>
      <mass value="1"/>
      <inertia ixx="0.05427083333333334" ixy="0.0" ixz="0.0" iyy="0.039427083333333335" iyz="0.0" izz="0.08526041666666667"/>
    </inertial>
  </link>
  <!-- Build leg -->
  <!-- joint to center of thorax -->
  <joint name="leg_center_joint_r1" type="fixed">
    <origin rpy="0 0 0" xyz="0.3875 -0.325 0"/>
    <parent link="thorax"/>
    <child link="leg_center_r1"/>
  </joint>
  <link name="leg_center_r1">
    <inertial>
      <origin rpy="1.5707963267948966 0 1.5707963267948966" xyz="0 0 0"/>
      <mass value="1"/>
      <inertia ixx="0.016927083333333332" ixy="0.0" ixz="0.0" iyy="0.017708333333333333" iyz="0.0" izz="0.0008854166666666668"/>
    </inertial>
  </link>
  <joint name="coxa_joint_r1" type="revolute">
    <origin rpy="0 0 -1.0471975511965976" xyz="0 0 0"/>
    <parent link="leg_center_r1"/>
    <child link="coxa_r1"/>
    <axis xyz="0 0 -1"/>
    <limit effort="10000" lower="-1.5" upper="1.5" velocity="100"/>
  </joint>
  <link name="coxa_r1">
    <visual>
      <origin rpy="0 0 0" xyz="0.04 -0.025 0"/>
      <geometry>
        <box size="0.16499999999999998 0.16499999999999998 0.16499999999999998"/>
        <!-- <mesh filename="package://crab_description/meshes/coxa_${side}.STL" /> -->
      </geometry>
      <material name="">
        <color rgba="0.7 0.7 0 1"/>
      </material>
    </visual>
    <collision>
      <origin rpy="0 0 0" xyz="0.04 -0.025 0"/>
      <geometry>
        <box size="0.16499999999999998 0.16499999999999998 0.16499999999999998"/>
        <!-- <mesh filename="package://crab_description/meshes/coxa_${side}.STL" /> -->
      </geometry>
      <material name="">
        <color rgba="0.7 0.7 0 1"/>
      </material>
    </collision>
    <inertial>
      <origin rpy="1.5707963267948966 0 1.5707963267948966" xyz="0 0 0"/>
      <mass value="1"/>
      <inertia ixx="0.004537499999999998" ixy="0.0" ixz="0.0" iyy="0.004537499999999998" iyz="0.0" izz="0.004537499999999998"/>
    </inertial>
  </link>
  <joint name="femur_joint_r1" type="revolute">
    <origin rpy="-1.5707963267948966 0 0" xyz="0.05 0 -0.05"/>
    <parent link="coxa_r1"/>
    <child link="femur_r1"/>
    <axis xyz="0 0 -1"/>
    <limit effort="10000" lower="-1.5" upper="1.5" velocity="100"/>
  </joint>
  <link name="femur_r1">
    <visual>
      <origin rpy="0 0 0" xyz="0.175 0 0"/>
      <geometry>
        <box size="0.35 0.075 0.02"/>
        <!-- <mesh filename="package://crab_description/meshes/femur_${side}.STL" /> -->
      </geometry>
      <material name="">
        <color rgba="0 0.7 0.7 1"/>
      </material>
    </visual>
    <collision>
      <origin rpy="0 0 0" xyz="0.175 0 0"/>
      <geometry>
        <box size="0.35 0.075 0.02"/>
        <!-- <mesh filename="package://crab_description/meshes/femur_${side}.STL" /> -->
      </geometry>
      <material name="">
        <color rgba="0 0.7 0.7 1"/>
      </material>
    </collision>
    <inertial>
      <origin rpy="1.5707963267948966 0 1.5707963267948966" xyz="0 0 0"/>
      <mass value="1"/>
      <inertia ixx="0.010241666666666665" ixy="0.0" ixz="0.0" iyy="0.010677083333333332" iyz="0.0" izz="0.0005020833333333333"/>
    </inertial>
  </link>
  <joint name="tibia_joint_r1" type="revolute">
    <origin rpy="3.141592653589793 0 1.5707963267948966" xyz="0.32999999999999996 0 0"/>
    <parent link="femur_r1"/>
    <child link="tibia_r1"/>
    <axis xyz="0 0 1"/>
    <limit effort="10000" lower="-1.5" upper="1.5" velocity="100"/>
  </joint>
  <link name="tibia_r1">
    <visual>
      <origin rpy="0 0 0.06" xyz="0.19 0 0.1"/>
      <geometry>
        <box size="0.45 0.1 0.025"/>
        <!-- <mesh filename="package://crab_description/meshes/tibia_${side}.STL" /> -->
      </geometry>
      <material name="">
        <color rgba="0.7 0 0.7 1"/>
      </material>
    </visual>
    <collision>
      <origin rpy="0 0 0.06" xyz="0.19 0 0.1"/>
      <geometry>
        <box size="0.45 0.1 0.025"/>
        <!-- <mesh filename="package://crab_description/meshes/tibia_${side}.STL" /> -->
      </geometry>
      <material name="">
        <color rgba="0.7 0 0.7 1"/>
      </material>
    </collision>
    <inertial>
      <origin rpy="1.5707963267948966 0 1.5707963267948966" xyz="0 0 0"/>
      <mass value="1"/>
      <inertia ixx="0.016927083333333332" ixy="0.0" ixz="0.0" iyy="0.017708333333333333" iyz="0.0" izz="0.0008854166666666668"/>
    </inertial>
  </link>
  <joint name="tibia_foot_joint_r1" type="fixed">
    <origin rpy="0 0 0" xyz="0.117 0 0"/>
    <parent link="tibia_r1"/>
    <child link="tibia_foot_r1"/>
  </joint>
  <link name="tibia_foot_r1"/>
  <!-- Build leg -->
  <!-- joint to center of thorax -->
  <joint name="leg_center_joint_r2" type="fixed">
    <origin rpy="0 0 0" xyz="0 -0.325 0"/>
    <parent link="thorax"/>
    <child link="leg_center_r2"/>
  </joint>
  <link name="leg_center_r2">
    <inertial>
      <origin rpy="1.5707963267948966 0 1.5707963267948966" xyz="0 0 0"/>
      <mass value="1"/>
      <inertia ixx="0.016927083333333332" ixy="0.0" ixz="0.0" iyy="0.017708333333333333" iyz="0.0" izz="0.0008854166666666668"/>
    </inertial>
  </link>
  <joint name="coxa_joint_r2" type="revolute">
    <origin rpy="0 0 -1.5707963267948966" xyz="0 0 0"/>
    <parent link="leg_center_r2"/>
    <child link="coxa_r2"/>
    <axis xyz="0 0 -1"/>
    <limit effort="10000" lower="-1.5" upper="1.5" velocity="100"/>
  </joint>
  <link name="coxa_r2">
    <visual>
      <origin rpy="0 0 0" xyz="0.04 -0.025 0"/>
      <geometry>
        <box size="0.16499999999999998 0.16499999999999998 0.16499999999999998"/>
        <!-- <mesh filename="package://crab_description/meshes/coxa_${side}.STL" /> -->
      </geometry>
      <material name="">
        <color rgba="0.7 0.7 0 1"/>
      </material>
    </visual>
    <collision>
      <origin rpy="0 0 0" xyz="0.04 -0.025 0"/>
      <geometry>
        <box size="0.16499999999999998 0.16499999999999998 0.16499999999999998"/>
        <!-- <mesh filename="package://crab_description/meshes/coxa_${side}.STL" /> -->
      </geometry>
      <material name="">
        <color rgba="0.7 0.7 0 1"/>
      </material>
    </collision>
    <inertial>
      <origin rpy="1.5707963267948966 0 1.5707963267948966" xyz="0 0 0"/>
      <mass value="1"/>
      <inertia ixx="0.004537499999999998" ixy="0.0" ixz="0.0" iyy="0.004537499999999998" iyz="0.0" izz="0.004537499999999998"/>
    </inertial>
  </link>
  <joint name="femur_joint_r2" type="revolute">
    <origin rpy="-1.5707963267948966 0 0" xyz="0.05 0 -0.05"/>
    <parent link="coxa_r2"/>
    <child link="femur_r2"/>
    <axis xyz="0 0 -1"/>
    <limit effort="10000" lower="-1.5" upper="1.5" velocity="100"/>
  </joint>
  <link name="femur_r2">
    <visual>
      <origin rpy="0 0 0" xyz="0.175 0 0"/>
      <geometry>
        <box size="0.35 0.075 0.02"/>
        <!-- <mesh filename="package://crab_description/meshes/femur_${side}.STL" /> -->
      </geometry>
      <material name="">
        <color rgba="0 0.7 0.7 1"/>
      </material>
    </visual>
    <collision>
      <origin rpy="0 0 0" xyz="0.175 0 0"/>
      <geometry>
        <box size="0.35 0.075 0.02"/>
        <!-- <mesh filename="package://crab_description/meshes/femur_${side}.STL" /> -->
      </geometry>
      <material name="">
        <color rgba="0 0.7 0.7 1"/>
      </material>
    </collision>
    <inertial>
      <origin rpy="1.5707963267948966 0 1.5707963267948966" xyz="0 0 0"/>
      <mass value="1"/>
      <inertia ixx="0.010241666666666665" ixy="0.0" ixz="0.0" iyy="0.010677083333333332" iyz="0.0" izz="0.0005020833333333333"/>
    </inertial>
  </link>
  <joint name="tibia_joint_r2" type="revolute">
    <origin rpy="3.141592653589793 0 1.5707963267948966" xyz="0.32999999999999996 0 0"/>
    <parent link="femur_r2"/>
    <child link="tibia_r2"/>
    <axis xyz="0 0 1"/>
    <limit effort="10000" lower="-1.5" upper="1.5" velocity="100"/>
  </joint>
  <link name="tibia_r2">
    <visual>
      <origin rpy="0 0 0.06" xyz="0.19 0 0.1"/>
      <geometry>
        <box size="0.45 0.1 0.025"/>
        <!-- <mesh filename="package://crab_description/meshes/tibia_${side}.STL" /> -->
      </geometry>
      <material name="">
        <color rgba="0.7 0 0.7 1"/>
      </material>
    </visual>
    <collision>
      <origin rpy="0 0 0.06" xyz="0.19 0 0.1"/>
      <geometry>
        <box size="0.45 0.1 0.025"/>
        <!-- <mesh filename="package://crab_description/meshes/tibia_${side}.STL" /> -->
      </geometry>
      <material name="">
        <color rgba="0.7 0 0.7 1"/>
      </material>
    </collision>
    <inertial>
      <origin rpy="1.5707963267948966 0 1.5707963267948966" xyz="0 0 0"/>
      <mass value="1"/>
      <inertia ixx="0.016927083333333332" ixy="0.0" ixz="0.0" iyy="0.017708333333333333" iyz="0.0" izz="0.0008854166666666668"/>
    </inertial>
  </link>
  <joint name="tibia_foot_joint_r2" type="fixed">
    <origin rpy="0 0 0" xyz="0.117 0 0"/>
    <parent link="tibia_r2"/>
    <child link="tibia_foot_r2"/>
  </joint>
  <link name="tibia_foot_r2"/>
  <!-- Build leg -->
  <!-- joint to center of thorax -->
  <joint name="leg_center_joint_r3" type="fixed">
    <origin rpy="0 0 0" xyz="-0.3875 -0.325 0"/>
    <parent link="thorax"/>
    <child link="leg_center_r3"/>
  </joint>
  <link name="leg_center_r3">
    <inertial>
      <origin rpy="1.5707963267948966 0 1.5707963267948966" xyz="0 0 0"/>
      <mass value="1"/>
      <inertia ixx="0.016927083333333332" ixy="0.0" ixz="0.0" iyy="0.017708333333333333" iyz="0.0" izz="0.0008854166666666668"/>
    </inertial>
  </link>
  <joint name="coxa_joint_r3" type="revolute">
    <origin rpy="0 0 -2.0943951023931953" xyz="0 0 0"/>
    <parent link="leg_center_r3"/>
    <child link="coxa_r3"/>
    <axis xyz="0 0 -1"/>
    <limit effort="10000" lower="-1.5" upper="1.5" velocity="100"/>
  </joint>
  <link name="coxa_r3">
    <visual>
      <origin rpy="0 0 0" xyz="0.04 -0.025 0"/>
      <geometry>
        <box size="0.16499999999999998 0.16499999999999998 0.16499999999999998"/>
        <!-- <mesh filename="package://crab_description/meshes/coxa_${side}.STL" /> -->
      </geometry>
      <material name="">
        <color rgba="0.7 0.7 0 1"/>
      </material>
    </visual>
    <collision>
      <origin rpy="0 0 0" xyz="0.04 -0.025 0"/>
      <geometry>
        <box size="0.16499999999999998 0.16499999999999998 0.16499999999999998"/>
        <!-- <mesh filename="package://crab_description/meshes/coxa_${side}.STL" /> -->
      </geometry>
      <material name="">
        <color rgba="0.7 0.7 0 1"/>
      </material>
    </collision>
    <inertial>
      <origin rpy="1.5707963267948966 0 1.5707963267948966" xyz="0 0 0"/>
      <mass value="1"/>
      <inertia ixx="0.004537499999999998" ixy="0.0" ixz="0.0" iyy="0.004537499999999998" iyz="0.0" izz="0.004537499999999998"/>
    </inertial>
  </link>
  <joint name="femur_joint_r3" type="revolute">
    <origin rpy="-1.5707963267948966 0 0" xyz="0.05 0 -0.05"/>
    <parent link="coxa_r3"/>
    <child link="femur_r3"/>
    <axis xyz="0 0 -1"/>
    <limit effort="10000" lower="-1.5" upper="1.5" velocity="100"/>
  </joint>
  <link name="femur_r3">
    <visual>
      <origin rpy="0 0 0" xyz="0.175 0 0"/>
      <geometry>
        <box size="0.35 0.075 0.02"/>
        <!-- <mesh filename="package://crab_description/meshes/femur_${side}.STL" /> -->
      </geometry>
      <material name="">
        <color rgba="0 0.7 0.7 1"/>
      </material>
    </visual>
    <collision>
      <origin rpy="0 0 0" xyz="0.175 0 0"/>
      <geometry>
        <box size="0.35 0.075 0.02"/>
        <!-- <mesh filename="package://crab_description/meshes/femur_${side}.STL" /> -->
      </geometry>
      <material name="">
        <color rgba="0 0.7 0.7 1"/>
      </material>
    </collision>
    <inertial>
      <origin rpy="1.5707963267948966 0 1.5707963267948966" xyz="0 0 0"/>
      <mass value="1"/>
      <inertia ixx="0.010241666666666665" ixy="0.0" ixz="0.0" iyy="0.010677083333333332" iyz="0.0" izz="0.0005020833333333333"/>
    </inertial>
  </link>
  <joint name="tibia_joint_r3" type="revolute">
    <origin rpy="3.141592653589793 0 1.5707963267948966" xyz="0.32999999999999996 0 0"/>
    <parent link="femur_r3"/>
    <child link="tibia_r3"/>
    <axis xyz="0 0 1"/>
    <limit effort="10000" lower="-1.5" upper="1.5" velocity="100"/>
  </joint>
  <link name="tibia_r3">
    <visual>
      <origin rpy="0 0 0.06" xyz="0.19 0 0.1"/>
      <geometry>
        <box size="0.45 0.1 0.025"/>
        <!-- <mesh filename="package://crab_description/meshes/tibia_${side}.STL" /> -->
      </geometry>
      <material name="">
        <color rgba="0.7 0 0.7 1"/>
      </material>
    </visual>
    <collision>
      <origin rpy="0 0 0.06" xyz="0.19 0 0.1"/>
      <geometry>
        <box size="0.45 0.1 0.025"/>
        <!-- <mesh filename="package://crab_description/meshes/tibia_${side}.STL" /> -->
      </geometry>
      <material name="">
        <color rgba="0.7 0 0.7 1"/>
      </material>
    </collision>
    <inertial>
      <origin rpy="1.5707963267948966 0 1.5707963267948966" xyz="0 0 0"/>
      <mass value="1"/>
      <inertia ixx="0.016927083333333332" ixy="0.0" ixz="0.0" iyy="0.017708333333333333" iyz="0.0" izz="0.0008854166666666668"/>
    </inertial>
  </link>
  <joint name="tibia_foot_joint_r3" type="fixed">
    <origin rpy="0 0 0" xyz="0.117 0 0"/>
    <parent link="tibia_r3"/>
    <child link="tibia_foot_r3"/>
  </joint>
  <link name="tibia_foot_r3"/>
  <!-- Build leg -->
  <!-- joint to center of thorax -->
  <joint name="leg_center_joint_l1" type="fixed">
    <origin rpy="0 0 0" xyz="0.3875 0.325 0"/>
    <parent link="thorax"/>
    <child link="leg_center_l1"/>
  </joint>
  <link name="leg_center_l1">
    <inertial>
      <origin rpy="1.5707963267948966 0 1.5707963267948966" xyz="0 0 0"/>
      <mass value="1"/>
      <inertia ixx="0.016927083333333332" ixy="0.0" ixz="0.0" iyy="0.017708333333333333" iyz="0.0" izz="0.0008854166666666668"/>
    </inertial>
  </link>
  <joint name="coxa_joint_l1" type="revolute">
    <origin rpy="0 0 1.0471975511965976" xyz="0 0 0"/>
    <parent link="leg_center_l1"/>
    <child link="coxa_l1"/>
    <axis xyz="0 0 -1"/>
    <limit effort="10000" lower="-1.5" upper="1.5" velocity="100"/>
  </joint>
  <link name="coxa_l1">
    <visual>
      <origin rpy="0 0 0" xyz="0.04 0.025 0"/>
      <geometry>
        <box size="0.16499999999999998 0.16499999999999998 0.16499999999999998"/>
        <!-- <mesh filename="package://crab_description/meshes/coxa_${side}.STL" /> -->
      </geometry>
      <material name="">
        <color rgba="0.7 0.7 0 1"/>
      </material>
    </visual>
    <collision>
      <origin rpy="0 0 0" xyz="0.04 0.025 0"/>
      <geometry>
        <box size="0.16499999999999998 0.16499999999999998 0.16499999999999998"/>
        <!-- <mesh filename="package://crab_description/meshes/coxa_${side}.STL" /> -->
      </geometry>
      <material name="">
        <color rgba="0.7 0.7 0 1"/>
      </material>
    </collision>
    <inertial>
      <origin rpy="1.5707963267948966 0 1.5707963267948966" xyz="0 0 0"/>
      <mass value="1"/>
      <inertia ixx="0.004537499999999998" ixy="0.0" ixz="0.0" iyy="0.004537499999999998" iyz="0.0" izz="0.004537499999999998"/>
    </inertial>
  </link>
  <joint name="femur_joint_l1" type="revolute">
    <origin rpy="-1.5707963267948966 0 0" xyz="0.05 0 -0.05"/>
    <parent link="coxa_l1"/>
    <child link="femur_l1"/>
    <axis xyz="0 0 -1"/>
    <limit effort="10000" lower="-1.5" upper="1.5" velocity="100"/>
  </joint>
  <link name="femur_l1">
    <visual>
      <origin rpy="0 0 0" xyz="0.175 0 0"/>
      <geometry>
        <box size="0.35 0.075 0.02"/>
        <!-- <mesh filename="package://crab_description/meshes/femur_${side}.STL" /> -->
      </geometry>
      <material name="">
        <color rgba="0 0.7 0.7 1"/>
      </material>
    </visual>
    <collision>
      <origin rpy="0 0 0" xyz="0.175 0 0"/>
      <geometry>
        <box size="0.35 0.075 0.02"/>
        <!-- <mesh filename="package://crab_description/meshes/femur_${side}.STL" /> -->
      </geometry>
      <material name="">
        <color rgba="0 0.7 0.7 1"/>
      </material>
    </collision>
    <inertial>
      <origin rpy="1.5707963267948966 0 1.5707963267948966" xyz="0 0 0"/>
      <mass value="1"/>
      <inertia ixx="0.010241666666666665" ixy="0.0" ixz="0.0" iyy="0.010677083333333332" iyz="0.0" izz="0.0005020833333333333"/>
    </inertial>
  </link>
  <joint name="tibia_joint_l1" type="revolute">
    <origin rpy="3.141592653589793 0 1.5707963267948966" xyz="0.32999999999999996 0 0"/>
    <parent link="femur_l1"/>
    <child link="tibia_l1"/>
    <axis xyz="0 0 1"/>
    <limit effort="10000" lower="-1.5" upper="1.5" velocity="100"/>
  </joint>
  <link name="tibia_l1">
    <visual>
      <origin rpy="0 0 0.06" xyz="0.19 0 0.1"/>
      <geometry>
        <box size="0.45 0.1 0.025"/>
        <!-- <mesh filename="package://crab_description/meshes/tibia_${side}.STL" /> -->
      </geometry>
      <material name="">
        <color rgba="0.7 0 0.7 1"/>
      </material>
    </visual>
    <collision>
      <origin rpy="0 0 0.06" xyz="0.19 0 0.1"/>
      <geometry>
        <box size="0.45 0.1 0.025"/>
        <!-- <mesh filename="package://crab_description/meshes/tibia_${side}.STL" /> -->
      </geometry>
      <material name="">
        <color rgba="0.7 0 0.7 1"/>
      </material>
    </collision>
    <inertial>
      <origin rpy="1.5707963267948966 0 1.5707963267948966" xyz="0 0 0"/>
      <mass value="1"/>
      <inertia ixx="0.016927083333333332" ixy="0.0" ixz="0.0" iyy="0.017708333333333333" iyz="0.0" izz="0.0008854166666666668"/>
    </inertial>
  </link>
  <joint name="tibia_foot_joint_l1" type="fixed">
    <origin rpy="0 0 0" xyz="0.117 0 0"/>
    <parent link="tibia_l1"/>
    <child link="tibia_foot_l1"/>
  </joint>
  <link name="tibia_foot_l1"/>
  <!-- Build leg -->
  <!-- joint to center of thorax -->
  <joint name="leg_center_joint_l2" type="fixed">
    <origin rpy="0 0 0" xyz="0 0.325 0"/>
    <parent link="thorax"/>
    <child link="leg_center_l2"/>
  </joint>
  <link name="leg_center_l2">
    <inertial>
      <origin rpy="1.5707963267948966 0 1.5707963267948966" xyz="0 0 0"/>
      <mass value="1"/>
      <inertia ixx="0.016927083333333332" ixy="0.0" ixz="0.0" iyy="0.017708333333333333" iyz="0.0" izz="0.0008854166666666668"/>
    </inertial>
  </link>
  <joint name="coxa_joint_l2" type="revolute">
    <origin rpy="0 0 1.5707963267948966" xyz="0 0 0"/>
    <parent link="leg_center_l2"/>
    <child link="coxa_l2"/>
    <axis xyz="0 0 -1"/>
    <limit effort="10000" lower="-1.5" upper="1.5" velocity="100"/>
  </joint>
  <link name="coxa_l2">
    <visual>
      <origin rpy="0 0 0" xyz="0.04 0.025 0"/>
      <geometry>
        <box size="0.16499999999999998 0.16499999999999998 0.16499999999999998"/>
        <!-- <mesh filename="package://crab_description/meshes/coxa_${side}.STL" /> -->
      </geometry>
      <material name="">
        <color rgba="0.7 0.7 0 1"/>
      </material>
    </visual>
    <collision>
      <origin rpy="0 0 0" xyz="0.04 0.025 0"/>
      <geometry>
        <box size="0.16499999999999998 0.16499999999999998 0.16499999999999998"/>
        <!-- <mesh filename="package://crab_description/meshes/coxa_${side}.STL" /> -->
      </geometry>
      <material name="">
        <color rgba="0.7 0.7 0 1"/>
      </material>
    </collision>
    <inertial>
      <origin rpy="1.5707963267948966 0 1.5707963267948966" xyz="0 0 0"/>
      <mass value="1"/>
      <inertia ixx="0.004537499999999998" ixy="0.0" ixz="0.0" iyy="0.004537499999999998" iyz="0.0" izz="0.004537499999999998"/>
    </inertial>
  </link>
  <joint name="femur_joint_l2" type="revolute">
    <origin rpy="-1.5707963267948966 0 0" xyz="0.05 0 -0.05"/>
    <parent link="coxa_l2"/>
    <child link="femur_l2"/>
    <axis xyz="0 0 -1"/>
    <limit effort="10000" lower="-1.5" upper="1.5" velocity="100"/>
  </joint>
  <link name="femur_l2">
    <visual>
      <origin rpy="0 0 0" xyz="0.175 0 0"/>
      <geometry>
        <box size="0.35 0.075 0.02"/>
        <!-- <mesh filename="package://crab_description/meshes/femur_${side}.STL" /> -->
      </geometry>
      <material name="">
        <color rgba="0 0.7 0.7 1"/>
      </material>
    </visual>
    <collision>
      <origin rpy="0 0 0" xyz="0.175 0 0"/>
      <geometry>
        <box size="0.35 0.075 0.02"/>
        <!-- <mesh filename="package://crab_description/meshes/femur_${side}.STL" /> -->
      </geometry>
      <material name="">
        <color rgba="0 0.7 0.7 1"/>
      </material>
    </collision>
    <inertial>
      <origin rpy="1.5707963267948966 0 1.5707963267948966" xyz="0 0 0"/>
      <mass value="1"/>
      <inertia ixx="0.010241666666666665" ixy="0.0" ixz="0.0" iyy="0.010677083333333332" iyz="0.0" izz="0.0005020833333333333"/>
    </inertial>
  </link>
  <joint name="tibia_joint_l2" type="revolute">
    <origin rpy="3.141592653589793 0 1.5707963267948966" xyz="0.32999999999999996 0 0"/>
    <parent link="femur_l2"/>
    <child link="tibia_l2"/>
    <axis xyz="0 0 1"/>
    <limit effort="10000" lower="-1.5" upper="1.5" velocity="100"/>
  </joint>
  <link name="tibia_l2">
    <visual>
      <origin rpy="0 0 0.06" xyz="0.19 0 0.1"/>
      <geometry>
        <box size="0.45 0.1 0.025"/>
        <!-- <mesh filename="package://crab_description/meshes/tibia_${side}.STL" /> -->
      </geometry>
      <material name="">
        <color rgba="0.7 0 0.7 1"/>
      </material>
    </visual>
    <collision>
      <origin rpy="0 0 0.06" xyz="0.19 0 0.1"/>
      <geometry>
        <box size="0.45 0.1 0.025"/>
        <!-- <mesh filename="package://crab_description/meshes/tibia_${side}.STL" /> -->
      </geometry>
      <material name="">
        <color rgba="0.7 0 0.7 1"/>
      </material>
    </collision>
    <inertial>
      <origin rpy="1.5707963267948966 0 1.5707963267948966" xyz="0 0 0"/>
      <mass value="1"/>
      <inertia ixx="0.016927083333333332" ixy="0.0" ixz="0.0" iyy="0.017708333333333333" iyz="0.0" izz="0.0008854166666666668"/>
    </inertial>
  </link>
  <joint name="tibia_foot_joint_l2" type="fixed">
    <origin rpy="0 0 0" xyz="0.117 0 0"/>
    <parent link="tibia_l2"/>
    <child link="tibia_foot_l2"/>
  </joint>
  <link name="tibia_foot_l2"/>
  <!-- Build leg -->
  <!-- joint to center of thorax -->
  <joint name="leg_center_joint_l3" type="fixed">
    <origin rpy="0 0 0" xyz="-0.3875 0.325 0"/>
    <parent link="thorax"/>
    <child link="leg_center_l3"/>
  </joint>
  <link name="leg_center_l3">
    <inertial>
      <origin rpy="1.5707963267948966 0 1.5707963267948966" xyz="0 0 0"/>
      <mass value="1"/>
      <inertia ixx="0.016927083333333332" ixy="0.0" ixz="0.0" iyy="0.017708333333333333" iyz="0.0" izz="0.0008854166666666668"/>
    </inertial>
  </link>
  <joint name="coxa_joint_l3" type="revolute">
    <origin rpy="0 0 2.0943951023931953" xyz="0 0 0"/>
    <parent link="leg_center_l3"/>
    <child link="coxa_l3"/>
    <axis xyz="0 0 -1"/>
    <limit effort="10000" lower="-1.5" upper="1.5" velocity="100"/>
  </joint>
  <link name="coxa_l3">
    <visual>
      <origin rpy="0 0 0" xyz="0.04 0.025 0"/>
      <geometry>
        <box size="0.16499999999999998 0.16499999999999998 0.16499999999999998"/>
        <!-- <mesh filename="package://crab_description/meshes/coxa_${side}.STL" /> -->
      </geometry>
      <material name="">
        <color rgba="0.7 0.7 0 1"/>
      </material>
    </visual>
    <collision>
      <origin rpy="0 0 0" xyz="0.04 0.025 0"/>
      <geometry>
        <box size="0.16499999999999998 0.16499999999999998 0.16499999999999998"/>
        <!-- <mesh filename="package://crab_description/meshes/coxa_${side}.STL" /> -->
      </geometry>
      <material name="">
        <color rgba="0.7 0.7 0 1"/>
      </material>
    </collision>
    <inertial>
      <origin rpy="1.5707963267948966 0 1.5707963267948966" xyz="0 0 0"/>
      <mass value="1"/>
      <inertia ixx="0.004537499999999998" ixy="0.0" ixz="0.0" iyy="0.004537499999999998" iyz="0.0" izz="0.004537499999999998"/>
    </inertial>
  </link>
  <joint name="femur_joint_l3" type="revolute">
    <origin rpy="-1.5707963267948966 0 0" xyz="0.05 0 -0.05"/>
    <parent link="coxa_l3"/>
    <child link="femur_l3"/>
    <axis xyz="0 0 -1"/>
    <limit effort="10000" lower="-1.5" upper="1.5" velocity="100"/>
  </joint>
  <link name="femur_l3">
    <visual>
      <origin rpy="0 0 0" xyz="0.175 0 0"/>
      <geometry>
        <box size="0.35 0.075 0.02"/>
        <!-- <mesh filename="package://crab_description/meshes/femur_${side}.STL" /> -->
      </geometry>
      <material name="">
        <color rgba="0 0.7 0.7 1"/>
      </material>
    </visual>
    <collision>
      <origin rpy="0 0 0" xyz="0.175 0 0"/>
      <geometry>
        <box size="0.35 0.075 0.02"/>
        <!-- <mesh filename="package://crab_description/meshes/femur_${side}.STL" /> -->
      </geometry>
      <material name="">
        <color rgba="0 0.7 0.7 1"/>
      </material>
    </collision>
    <inertial>
      <origin rpy="1.5707963267948966 0 1.5707963267948966" xyz="0 0 0"/>
      <mass value="1"/>
      <inertia ixx="0.010241666666666665" ixy="0.0" ixz="0.0" iyy="0.010677083333333332" iyz="0.0" izz="0.0005020833333333333"/>
    </inertial>
  </link>
  <joint name="tibia_joint_l3" type="revolute">
    <origin rpy="3.141592653589793 0 1.5707963267948966" xyz="0.32999999999999996 0 0"/>
    <parent link="femur_l3"/>
    <child link="tibia_l3"/>
    <axis xyz="0 0 1"/>
    <limit effort="10000" lower="-1.5" upper="1.5" velocity="100"/>
  </joint>
  <link name="tibia_l3">
    <visual>
      <origin rpy="0 0 0.06" xyz="0.19 0 0.1"/>
      <geometry>
        <box size="0.45 0.1 0.025"/>
        <!-- <mesh filename="package://crab_description/meshes/tibia_${side}.STL" /> -->
      </geometry>
      <material name="">
        <color rgba="0.7 0 0.7 1"/>
      </material>
    </visual>
    <collision>
      <origin rpy="0 0 0.06" xyz="0.19 0 0.1"/>
      <geometry>
        <box size="0.45 0.1 0.025"/>
        <!-- <mesh filename="package://crab_description/meshes/tibia_${side}.STL" /> -->
      </geometry>
      <material name="">
        <color rgba="0.7 0 0.7 1"/>
      </material>
    </collision>
    <inertial>
      <origin rpy="1.5707963267948966 0 1.5707963267948966" xyz="0 0 0"/>
      <mass value="1"/>
      <inertia ixx="0.016927083333333332" ixy="0.0" ixz="0.0" iyy="0.017708333333333333" iyz="0.0" izz="0.0008854166666666668"/>
    </inertial>
  </link>
  <joint name="tibia_foot_joint_l3" type="fixed">
    <origin rpy="0 0 0" xyz="0.117 0 0"/>
    <parent link="tibia_l3"/>
    <child link="tibia_foot_l3"/>
  </joint>
  <link name="tibia_foot_l3"/>
</robot>

